WARNING 2022-05-11 13:21:11,872 [Thread-1:6169194496] [django.request:241] [log:log_response] [WARNING]- Not Found: /
WARNING 2022-05-11 13:33:14,293 [Thread-1:6199980032] [django.request:241] [log:log_response] [WARNING]- Not Found: /favicon.ico
ERROR 2022-05-13 02:22:14,072 [Thread-5:6185840640] [django.request:241] [log:log_response] [ERROR]- Internal Server Error: /api/uploadImage/
Traceback (most recent call last):
  File "/Users/key/PycharmProjects/python_dip_courseproject_django/venv/lib/python3.8/site-packages/django/core/handlers/exception.py", line 55, in inner
    response = get_response(request)
  File "/Users/key/PycharmProjects/python_dip_courseproject_django/venv/lib/python3.8/site-packages/django/core/handlers/base.py", line 197, in _get_response
    response = wrapped_callback(request, *callback_args, **callback_kwargs)
  File "/Users/key/PycharmProjects/python_dip_courseproject_django/api/views.py", line 19, in receive_image
    print(request.data)
AttributeError: 'WSGIRequest' object has no attribute 'data'
ERROR 2022-05-13 02:23:51,684 [Thread-5:6172602368] [django.request:241] [log:log_response] [ERROR]- Internal Server Error: /api/uploadImage/
Traceback (most recent call last):
  File "/Users/key/PycharmProjects/python_dip_courseproject_django/venv/lib/python3.8/site-packages/django/core/handlers/exception.py", line 55, in inner
    response = get_response(request)
  File "/Users/key/PycharmProjects/python_dip_courseproject_django/venv/lib/python3.8/site-packages/django/core/handlers/base.py", line 197, in _get_response
    response = wrapped_callback(request, *callback_args, **callback_kwargs)
  File "/Users/key/PycharmProjects/python_dip_courseproject_django/api/views.py", line 19, in receive_image
    print(request.data)
AttributeError: 'WSGIRequest' object has no attribute 'data'
ERROR 2022-05-13 02:24:04,662 [Thread-5:6245593088] [django.request:241] [log:log_response] [ERROR]- Internal Server Error: /api/uploadImage/
Traceback (most recent call last):
  File "/Users/key/PycharmProjects/python_dip_courseproject_django/venv/lib/python3.8/site-packages/django/core/handlers/exception.py", line 55, in inner
    response = get_response(request)
  File "/Users/key/PycharmProjects/python_dip_courseproject_django/venv/lib/python3.8/site-packages/django/core/handlers/base.py", line 197, in _get_response
    response = wrapped_callback(request, *callback_args, **callback_kwargs)
  File "/Users/key/PycharmProjects/python_dip_courseproject_django/api/views.py", line 19, in receive_image
    print(request.data)
AttributeError: 'WSGIRequest' object has no attribute 'data'
ERROR 2022-05-13 02:24:38,382 [Thread-5:6247444480] [django.request:241] [log:log_response] [ERROR]- Internal Server Error: /api/uploadImage/
Traceback (most recent call last):
  File "/Users/key/PycharmProjects/python_dip_courseproject_django/venv/lib/python3.8/site-packages/django/core/handlers/exception.py", line 55, in inner
    response = get_response(request)
  File "/Users/key/PycharmProjects/python_dip_courseproject_django/venv/lib/python3.8/site-packages/django/core/handlers/base.py", line 197, in _get_response
    response = wrapped_callback(request, *callback_args, **callback_kwargs)
  File "/Users/key/PycharmProjects/python_dip_courseproject_django/api/views.py", line 19, in receive_image
    print(request.data)
AttributeError: 'WSGIRequest' object has no attribute 'data'
ERROR 2022-05-13 02:32:26,613 [Thread-1:6189412352] [django.request:241] [log:log_response] [ERROR]- Internal Server Error: /api/uploadImage/
Traceback (most recent call last):
  File "/Users/key/PycharmProjects/python_dip_courseproject_django/venv/lib/python3.8/site-packages/django/core/handlers/exception.py", line 55, in inner
    response = get_response(request)
  File "/Users/key/PycharmProjects/python_dip_courseproject_django/venv/lib/python3.8/site-packages/django/core/handlers/base.py", line 197, in _get_response
    response = wrapped_callback(request, *callback_args, **callback_kwargs)
  File "/Users/key/PycharmProjects/python_dip_courseproject_django/api/views.py", line 24, in receive_image
    print(request.data)
AttributeError: 'WSGIRequest' object has no attribute 'data'
ERROR 2022-05-13 02:41:31,874 [Thread-1:6202077184] [django.request:241] [log:log_response] [ERROR]- Internal Server Error: /api/uploadImage/
Traceback (most recent call last):
  File "/Users/key/PycharmProjects/python_dip_courseproject_django/venv/lib/python3.8/site-packages/django/core/handlers/exception.py", line 55, in inner
    response = get_response(request)
  File "/Users/key/PycharmProjects/python_dip_courseproject_django/venv/lib/python3.8/site-packages/django/core/handlers/base.py", line 197, in _get_response
    response = wrapped_callback(request, *callback_args, **callback_kwargs)
  File "/Users/key/PycharmProjects/python_dip_courseproject_django/api/views.py", line 19, in receive_image
    serializer = ImageSerializer(data=request.data)
AttributeError: 'WSGIRequest' object has no attribute 'data'
ERROR 2022-05-13 02:46:00,055 [Thread-5:6249787392] [django.request:241] [log:log_response] [ERROR]- Internal Server Error: /api/uploadImage/
Traceback (most recent call last):
  File "/Users/key/PycharmProjects/python_dip_courseproject_django/venv/lib/python3.8/site-packages/django/core/handlers/exception.py", line 55, in inner
    response = get_response(request)
  File "/Users/key/PycharmProjects/python_dip_courseproject_django/venv/lib/python3.8/site-packages/django/core/handlers/base.py", line 197, in _get_response
    response = wrapped_callback(request, *callback_args, **callback_kwargs)
  File "/Users/key/PycharmProjects/python_dip_courseproject_django/api/views.py", line 19, in receive_image
    serializer = ImageSerializer(data=request.data)
AttributeError: 'WSGIRequest' object has no attribute 'data'
ERROR 2022-05-13 02:46:44,449 [Thread-5:6174814208] [django.request:241] [log:log_response] [ERROR]- Internal Server Error: /api/uploadImage/
Traceback (most recent call last):
  File "/Users/key/PycharmProjects/python_dip_courseproject_django/venv/lib/python3.8/site-packages/django/core/handlers/exception.py", line 55, in inner
    response = get_response(request)
  File "/Users/key/PycharmProjects/python_dip_courseproject_django/venv/lib/python3.8/site-packages/django/core/handlers/base.py", line 197, in _get_response
    response = wrapped_callback(request, *callback_args, **callback_kwargs)
  File "/Users/key/PycharmProjects/python_dip_courseproject_django/api/views.py", line 19, in receive_image
    serializer = ImageSerializer(data=request.FILES.file)
AttributeError: 'MultiValueDict' object has no attribute 'file'
ERROR 2022-05-13 02:52:07,408 [Thread-1:6196310016] [django.request:241] [log:log_response] [ERROR]- Internal Server Error: /api/uploadImage/
Traceback (most recent call last):
  File "/Users/key/PycharmProjects/python_dip_courseproject_django/venv/lib/python3.8/site-packages/django/core/handlers/exception.py", line 55, in inner
    response = get_response(request)
  File "/Users/key/PycharmProjects/python_dip_courseproject_django/venv/lib/python3.8/site-packages/django/core/handlers/base.py", line 204, in _get_response
    self.check_response(response, callback)
  File "/Users/key/PycharmProjects/python_dip_courseproject_django/venv/lib/python3.8/site-packages/django/core/handlers/base.py", line 332, in check_response
    raise ValueError(
ValueError: The view api.views.receive_image didn't return an HttpResponse object. It returned None instead.
ERROR 2022-05-13 02:52:26,322 [Thread-1:6191624192] [django.request:241] [log:log_response] [ERROR]- Internal Server Error: /api/uploadImage/
Traceback (most recent call last):
  File "/Users/key/PycharmProjects/python_dip_courseproject_django/venv/lib/python3.8/site-packages/django/core/handlers/exception.py", line 55, in inner
    response = get_response(request)
  File "/Users/key/PycharmProjects/python_dip_courseproject_django/venv/lib/python3.8/site-packages/django/core/handlers/base.py", line 197, in _get_response
    response = wrapped_callback(request, *callback_args, **callback_kwargs)
  File "/Users/key/PycharmProjects/python_dip_courseproject_django/api/views.py", line 22, in receive_image
    return success(serializer_class)
  File "/Users/key/PycharmProjects/python_dip_courseproject_django/lib/utils/json_response.py", line 17, in success
    return result(code=HttpCode.success, message='OK', data=data)
  File "/Users/key/PycharmProjects/python_dip_courseproject_django/lib/utils/json_response.py", line 13, in result
    return JsonResponse(json_dict, json_dumps_params={'ensure_ascii': False})
  File "/Users/key/PycharmProjects/python_dip_courseproject_django/venv/lib/python3.8/site-packages/django/http/response.py", line 653, in __init__
    data = json.dumps(data, cls=encoder, **json_dumps_params)
  File "/Library/Developer/CommandLineTools/Library/Frameworks/Python3.framework/Versions/3.8/lib/python3.8/json/__init__.py", line 234, in dumps
    return cls(
  File "/Library/Developer/CommandLineTools/Library/Frameworks/Python3.framework/Versions/3.8/lib/python3.8/json/encoder.py", line 199, in encode
    chunks = self.iterencode(o, _one_shot=True)
  File "/Library/Developer/CommandLineTools/Library/Frameworks/Python3.framework/Versions/3.8/lib/python3.8/json/encoder.py", line 257, in iterencode
    return _iterencode(o, 0)
  File "/Users/key/PycharmProjects/python_dip_courseproject_django/venv/lib/python3.8/site-packages/django/core/serializers/json.py", line 106, in default
    return super().default(o)
  File "/Library/Developer/CommandLineTools/Library/Frameworks/Python3.framework/Versions/3.8/lib/python3.8/json/encoder.py", line 179, in default
    raise TypeError(f'Object of type {o.__class__.__name__} '
TypeError: Object of type SerializerMetaclass is not JSON serializable
ERROR 2022-05-13 02:54:31,823 [Thread-1:6167474176] [django.request:241] [log:log_response] [ERROR]- Internal Server Error: /api/uploadImage/
Traceback (most recent call last):
  File "/Users/key/PycharmProjects/python_dip_courseproject_django/venv/lib/python3.8/site-packages/django/core/handlers/exception.py", line 55, in inner
    response = get_response(request)
  File "/Users/key/PycharmProjects/python_dip_courseproject_django/venv/lib/python3.8/site-packages/django/core/handlers/base.py", line 204, in _get_response
    self.check_response(response, callback)
  File "/Users/key/PycharmProjects/python_dip_courseproject_django/venv/lib/python3.8/site-packages/django/core/handlers/base.py", line 332, in check_response
    raise ValueError(
ValueError: The view api.views.receive_image didn't return an HttpResponse object. It returned None instead.
WARNING 2022-05-13 03:03:06,666 [Thread-1:6165770240] [django.request:241] [log:log_response] [WARNING]- Not Found: /api/uploadImage/
WARNING 2022-05-13 03:03:57,918 [Thread-1:6166933504] [django.request:241] [log:log_response] [WARNING]- Not Found: /api/uploadImage/
WARNING 2022-05-13 03:04:52,095 [Thread-1:6197850112] [django.request:241] [log:log_response] [WARNING]- Not Found: /api/uploadImage/
