WARNING 2022-05-11 13:21:11,872 [Thread-1:6169194496] [django.request:241] [log:log_response] [WARNING]- Not Found: /
WARNING 2022-05-11 13:33:14,293 [Thread-1:6199980032] [django.request:241] [log:log_response] [WARNING]- Not Found: /favicon.ico
ERROR 2022-05-13 02:22:14,072 [Thread-5:6185840640] [django.request:241] [log:log_response] [ERROR]- Internal Server Error: /api/uploadImage/
Traceback (most recent call last):
  File "/Users/key/PycharmProjects/python_dip_courseproject_django/venv/lib/python3.8/site-packages/django/core/handlers/exception.py", line 55, in inner
    response = get_response(request)
  File "/Users/key/PycharmProjects/python_dip_courseproject_django/venv/lib/python3.8/site-packages/django/core/handlers/base.py", line 197, in _get_response
    response = wrapped_callback(request, *callback_args, **callback_kwargs)
  File "/Users/key/PycharmProjects/python_dip_courseproject_django/api/views.py", line 19, in receive_image
    print(request.data)
AttributeError: 'WSGIRequest' object has no attribute 'data'
ERROR 2022-05-13 02:23:51,684 [Thread-5:6172602368] [django.request:241] [log:log_response] [ERROR]- Internal Server Error: /api/uploadImage/
Traceback (most recent call last):
  File "/Users/key/PycharmProjects/python_dip_courseproject_django/venv/lib/python3.8/site-packages/django/core/handlers/exception.py", line 55, in inner
    response = get_response(request)
  File "/Users/key/PycharmProjects/python_dip_courseproject_django/venv/lib/python3.8/site-packages/django/core/handlers/base.py", line 197, in _get_response
    response = wrapped_callback(request, *callback_args, **callback_kwargs)
  File "/Users/key/PycharmProjects/python_dip_courseproject_django/api/views.py", line 19, in receive_image
    print(request.data)
AttributeError: 'WSGIRequest' object has no attribute 'data'
ERROR 2022-05-13 02:24:04,662 [Thread-5:6245593088] [django.request:241] [log:log_response] [ERROR]- Internal Server Error: /api/uploadImage/
Traceback (most recent call last):
  File "/Users/key/PycharmProjects/python_dip_courseproject_django/venv/lib/python3.8/site-packages/django/core/handlers/exception.py", line 55, in inner
    response = get_response(request)
  File "/Users/key/PycharmProjects/python_dip_courseproject_django/venv/lib/python3.8/site-packages/django/core/handlers/base.py", line 197, in _get_response
    response = wrapped_callback(request, *callback_args, **callback_kwargs)
  File "/Users/key/PycharmProjects/python_dip_courseproject_django/api/views.py", line 19, in receive_image
    print(request.data)
AttributeError: 'WSGIRequest' object has no attribute 'data'
ERROR 2022-05-13 02:24:38,382 [Thread-5:6247444480] [django.request:241] [log:log_response] [ERROR]- Internal Server Error: /api/uploadImage/
Traceback (most recent call last):
  File "/Users/key/PycharmProjects/python_dip_courseproject_django/venv/lib/python3.8/site-packages/django/core/handlers/exception.py", line 55, in inner
    response = get_response(request)
  File "/Users/key/PycharmProjects/python_dip_courseproject_django/venv/lib/python3.8/site-packages/django/core/handlers/base.py", line 197, in _get_response
    response = wrapped_callback(request, *callback_args, **callback_kwargs)
  File "/Users/key/PycharmProjects/python_dip_courseproject_django/api/views.py", line 19, in receive_image
    print(request.data)
AttributeError: 'WSGIRequest' object has no attribute 'data'
ERROR 2022-05-13 02:32:26,613 [Thread-1:6189412352] [django.request:241] [log:log_response] [ERROR]- Internal Server Error: /api/uploadImage/
Traceback (most recent call last):
  File "/Users/key/PycharmProjects/python_dip_courseproject_django/venv/lib/python3.8/site-packages/django/core/handlers/exception.py", line 55, in inner
    response = get_response(request)
  File "/Users/key/PycharmProjects/python_dip_courseproject_django/venv/lib/python3.8/site-packages/django/core/handlers/base.py", line 197, in _get_response
    response = wrapped_callback(request, *callback_args, **callback_kwargs)
  File "/Users/key/PycharmProjects/python_dip_courseproject_django/api/views.py", line 24, in receive_image
    print(request.data)
AttributeError: 'WSGIRequest' object has no attribute 'data'
ERROR 2022-05-13 02:41:31,874 [Thread-1:6202077184] [django.request:241] [log:log_response] [ERROR]- Internal Server Error: /api/uploadImage/
Traceback (most recent call last):
  File "/Users/key/PycharmProjects/python_dip_courseproject_django/venv/lib/python3.8/site-packages/django/core/handlers/exception.py", line 55, in inner
    response = get_response(request)
  File "/Users/key/PycharmProjects/python_dip_courseproject_django/venv/lib/python3.8/site-packages/django/core/handlers/base.py", line 197, in _get_response
    response = wrapped_callback(request, *callback_args, **callback_kwargs)
  File "/Users/key/PycharmProjects/python_dip_courseproject_django/api/views.py", line 19, in receive_image
    serializer = ImageSerializer(data=request.data)
AttributeError: 'WSGIRequest' object has no attribute 'data'
ERROR 2022-05-13 02:46:00,055 [Thread-5:6249787392] [django.request:241] [log:log_response] [ERROR]- Internal Server Error: /api/uploadImage/
Traceback (most recent call last):
  File "/Users/key/PycharmProjects/python_dip_courseproject_django/venv/lib/python3.8/site-packages/django/core/handlers/exception.py", line 55, in inner
    response = get_response(request)
  File "/Users/key/PycharmProjects/python_dip_courseproject_django/venv/lib/python3.8/site-packages/django/core/handlers/base.py", line 197, in _get_response
    response = wrapped_callback(request, *callback_args, **callback_kwargs)
  File "/Users/key/PycharmProjects/python_dip_courseproject_django/api/views.py", line 19, in receive_image
    serializer = ImageSerializer(data=request.data)
AttributeError: 'WSGIRequest' object has no attribute 'data'
ERROR 2022-05-13 02:46:44,449 [Thread-5:6174814208] [django.request:241] [log:log_response] [ERROR]- Internal Server Error: /api/uploadImage/
Traceback (most recent call last):
  File "/Users/key/PycharmProjects/python_dip_courseproject_django/venv/lib/python3.8/site-packages/django/core/handlers/exception.py", line 55, in inner
    response = get_response(request)
  File "/Users/key/PycharmProjects/python_dip_courseproject_django/venv/lib/python3.8/site-packages/django/core/handlers/base.py", line 197, in _get_response
    response = wrapped_callback(request, *callback_args, **callback_kwargs)
  File "/Users/key/PycharmProjects/python_dip_courseproject_django/api/views.py", line 19, in receive_image
    serializer = ImageSerializer(data=request.FILES.file)
AttributeError: 'MultiValueDict' object has no attribute 'file'
ERROR 2022-05-13 02:52:07,408 [Thread-1:6196310016] [django.request:241] [log:log_response] [ERROR]- Internal Server Error: /api/uploadImage/
Traceback (most recent call last):
  File "/Users/key/PycharmProjects/python_dip_courseproject_django/venv/lib/python3.8/site-packages/django/core/handlers/exception.py", line 55, in inner
    response = get_response(request)
  File "/Users/key/PycharmProjects/python_dip_courseproject_django/venv/lib/python3.8/site-packages/django/core/handlers/base.py", line 204, in _get_response
    self.check_response(response, callback)
  File "/Users/key/PycharmProjects/python_dip_courseproject_django/venv/lib/python3.8/site-packages/django/core/handlers/base.py", line 332, in check_response
    raise ValueError(
ValueError: The view api.views.receive_image didn't return an HttpResponse object. It returned None instead.
ERROR 2022-05-13 02:52:26,322 [Thread-1:6191624192] [django.request:241] [log:log_response] [ERROR]- Internal Server Error: /api/uploadImage/
Traceback (most recent call last):
  File "/Users/key/PycharmProjects/python_dip_courseproject_django/venv/lib/python3.8/site-packages/django/core/handlers/exception.py", line 55, in inner
    response = get_response(request)
  File "/Users/key/PycharmProjects/python_dip_courseproject_django/venv/lib/python3.8/site-packages/django/core/handlers/base.py", line 197, in _get_response
    response = wrapped_callback(request, *callback_args, **callback_kwargs)
  File "/Users/key/PycharmProjects/python_dip_courseproject_django/api/views.py", line 22, in receive_image
    return success(serializer_class)
  File "/Users/key/PycharmProjects/python_dip_courseproject_django/lib/utils/json_response.py", line 17, in success
    return result(code=HttpCode.success, message='OK', data=data)
  File "/Users/key/PycharmProjects/python_dip_courseproject_django/lib/utils/json_response.py", line 13, in result
    return JsonResponse(json_dict, json_dumps_params={'ensure_ascii': False})
  File "/Users/key/PycharmProjects/python_dip_courseproject_django/venv/lib/python3.8/site-packages/django/http/response.py", line 653, in __init__
    data = json.dumps(data, cls=encoder, **json_dumps_params)
  File "/Library/Developer/CommandLineTools/Library/Frameworks/Python3.framework/Versions/3.8/lib/python3.8/json/__init__.py", line 234, in dumps
    return cls(
  File "/Library/Developer/CommandLineTools/Library/Frameworks/Python3.framework/Versions/3.8/lib/python3.8/json/encoder.py", line 199, in encode
    chunks = self.iterencode(o, _one_shot=True)
  File "/Library/Developer/CommandLineTools/Library/Frameworks/Python3.framework/Versions/3.8/lib/python3.8/json/encoder.py", line 257, in iterencode
    return _iterencode(o, 0)
  File "/Users/key/PycharmProjects/python_dip_courseproject_django/venv/lib/python3.8/site-packages/django/core/serializers/json.py", line 106, in default
    return super().default(o)
  File "/Library/Developer/CommandLineTools/Library/Frameworks/Python3.framework/Versions/3.8/lib/python3.8/json/encoder.py", line 179, in default
    raise TypeError(f'Object of type {o.__class__.__name__} '
TypeError: Object of type SerializerMetaclass is not JSON serializable
ERROR 2022-05-13 02:54:31,823 [Thread-1:6167474176] [django.request:241] [log:log_response] [ERROR]- Internal Server Error: /api/uploadImage/
Traceback (most recent call last):
  File "/Users/key/PycharmProjects/python_dip_courseproject_django/venv/lib/python3.8/site-packages/django/core/handlers/exception.py", line 55, in inner
    response = get_response(request)
  File "/Users/key/PycharmProjects/python_dip_courseproject_django/venv/lib/python3.8/site-packages/django/core/handlers/base.py", line 204, in _get_response
    self.check_response(response, callback)
  File "/Users/key/PycharmProjects/python_dip_courseproject_django/venv/lib/python3.8/site-packages/django/core/handlers/base.py", line 332, in check_response
    raise ValueError(
ValueError: The view api.views.receive_image didn't return an HttpResponse object. It returned None instead.
WARNING 2022-05-13 03:03:06,666 [Thread-1:6165770240] [django.request:241] [log:log_response] [WARNING]- Not Found: /api/uploadImage/
WARNING 2022-05-13 03:03:57,918 [Thread-1:6166933504] [django.request:241] [log:log_response] [WARNING]- Not Found: /api/uploadImage/
WARNING 2022-05-13 03:04:52,095 [Thread-1:6197850112] [django.request:241] [log:log_response] [WARNING]- Not Found: /api/uploadImage/
WARNING 2022-05-13 08:55:33,005 [Thread-1:6204436480] [django.request:241] [log:log_response] [WARNING]- Not Found: /api/receive_image
WARNING 2022-05-13 08:55:36,635 [Thread-1:6204436480] [django.request:241] [log:log_response] [WARNING]- Not Found: /api/receive_image/
WARNING 2022-05-13 09:28:05,972 [Thread-1:6192803840] [django.request:241] [log:log_response] [WARNING]- Not Found: /
WARNING 2022-05-13 09:29:54,176 [Thread-2:6209630208] [django.request:241] [log:log_response] [WARNING]- Not Found: /
ERROR 2022-05-13 14:49:24,586 [Thread-1:6128513024] [django.request:241] [log:log_response] [ERROR]- Internal Server Error: /api/
Traceback (most recent call last):
  File "/Users/key/PycharmProjects/python_dip_courseproject_django/venv/lib/python3.8/site-packages/django/core/handlers/exception.py", line 55, in inner
    response = get_response(request)
  File "/Users/key/PycharmProjects/python_dip_courseproject_django/venv/lib/python3.8/site-packages/django/core/handlers/base.py", line 220, in _get_response
    response = response.render()
  File "/Users/key/PycharmProjects/python_dip_courseproject_django/venv/lib/python3.8/site-packages/django/template/response.py", line 114, in render
    self.content = self.rendered_content
  File "/Users/key/PycharmProjects/python_dip_courseproject_django/venv/lib/python3.8/site-packages/rest_framework/response.py", line 55, in rendered_content
    assert renderer, ".accepted_renderer not set on Response"
AssertionError: .accepted_renderer not set on Response
ERROR 2022-05-13 14:49:32,100 [Thread-1:6128513024] [django.request:241] [log:log_response] [ERROR]- Internal Server Error: /api/
Traceback (most recent call last):
  File "/Users/key/PycharmProjects/python_dip_courseproject_django/venv/lib/python3.8/site-packages/django/core/handlers/exception.py", line 55, in inner
    response = get_response(request)
  File "/Users/key/PycharmProjects/python_dip_courseproject_django/venv/lib/python3.8/site-packages/django/core/handlers/base.py", line 220, in _get_response
    response = response.render()
  File "/Users/key/PycharmProjects/python_dip_courseproject_django/venv/lib/python3.8/site-packages/django/template/response.py", line 114, in render
    self.content = self.rendered_content
  File "/Users/key/PycharmProjects/python_dip_courseproject_django/venv/lib/python3.8/site-packages/rest_framework/response.py", line 55, in rendered_content
    assert renderer, ".accepted_renderer not set on Response"
AssertionError: .accepted_renderer not set on Response
ERROR 2022-05-13 14:49:36,371 [Thread-1:6128513024] [django.request:241] [log:log_response] [ERROR]- Internal Server Error: /api/ImageAPI/
Traceback (most recent call last):
  File "/Users/key/PycharmProjects/python_dip_courseproject_django/venv/lib/python3.8/site-packages/django/core/handlers/exception.py", line 55, in inner
    response = get_response(request)
  File "/Users/key/PycharmProjects/python_dip_courseproject_django/venv/lib/python3.8/site-packages/django/core/handlers/base.py", line 197, in _get_response
    response = wrapped_callback(request, *callback_args, **callback_kwargs)
  File "/Users/key/PycharmProjects/python_dip_courseproject_django/venv/lib/python3.8/site-packages/django/views/decorators/csrf.py", line 54, in wrapped_view
    return view_func(*args, **kwargs)
  File "/Users/key/PycharmProjects/python_dip_courseproject_django/venv/lib/python3.8/site-packages/django/views/generic/base.py", line 84, in view
    return self.dispatch(request, *args, **kwargs)
  File "/Users/key/PycharmProjects/python_dip_courseproject_django/venv/lib/python3.8/site-packages/rest_framework/views.py", line 509, in dispatch
    response = self.handle_exception(exc)
  File "/Users/key/PycharmProjects/python_dip_courseproject_django/venv/lib/python3.8/site-packages/rest_framework/views.py", line 469, in handle_exception
    self.raise_uncaught_exception(exc)
  File "/Users/key/PycharmProjects/python_dip_courseproject_django/venv/lib/python3.8/site-packages/rest_framework/views.py", line 480, in raise_uncaught_exception
    raise exc
  File "/Users/key/PycharmProjects/python_dip_courseproject_django/venv/lib/python3.8/site-packages/rest_framework/views.py", line 506, in dispatch
    response = handler(request, *args, **kwargs)
  File "/Users/key/PycharmProjects/python_dip_courseproject_django/api/views.py", line 26, in get
    images = Image.objects.all()
AttributeError: type object 'Image' has no attribute 'objects'
ERROR 2022-05-13 14:49:42,378 [Thread-1:6128513024] [django.request:241] [log:log_response] [ERROR]- Internal Server Error: /api/
Traceback (most recent call last):
  File "/Users/key/PycharmProjects/python_dip_courseproject_django/venv/lib/python3.8/site-packages/django/core/handlers/exception.py", line 55, in inner
    response = get_response(request)
  File "/Users/key/PycharmProjects/python_dip_courseproject_django/venv/lib/python3.8/site-packages/django/core/handlers/base.py", line 220, in _get_response
    response = response.render()
  File "/Users/key/PycharmProjects/python_dip_courseproject_django/venv/lib/python3.8/site-packages/django/template/response.py", line 114, in render
    self.content = self.rendered_content
  File "/Users/key/PycharmProjects/python_dip_courseproject_django/venv/lib/python3.8/site-packages/rest_framework/response.py", line 55, in rendered_content
    assert renderer, ".accepted_renderer not set on Response"
AssertionError: .accepted_renderer not set on Response
ERROR 2022-05-13 14:49:48,406 [Thread-1:6128513024] [django.request:241] [log:log_response] [ERROR]- Internal Server Error: /api/
Traceback (most recent call last):
  File "/Users/key/PycharmProjects/python_dip_courseproject_django/venv/lib/python3.8/site-packages/django/core/handlers/exception.py", line 55, in inner
    response = get_response(request)
  File "/Users/key/PycharmProjects/python_dip_courseproject_django/venv/lib/python3.8/site-packages/django/core/handlers/base.py", line 220, in _get_response
    response = response.render()
  File "/Users/key/PycharmProjects/python_dip_courseproject_django/venv/lib/python3.8/site-packages/django/template/response.py", line 114, in render
    self.content = self.rendered_content
  File "/Users/key/PycharmProjects/python_dip_courseproject_django/venv/lib/python3.8/site-packages/rest_framework/response.py", line 55, in rendered_content
    assert renderer, ".accepted_renderer not set on Response"
AssertionError: .accepted_renderer not set on Response
ERROR 2022-05-13 14:50:20,770 [Thread-1:6192820224] [django.request:241] [log:log_response] [ERROR]- Internal Server Error: /api/
Traceback (most recent call last):
  File "/Users/key/PycharmProjects/python_dip_courseproject_django/venv/lib/python3.8/site-packages/django/core/handlers/exception.py", line 55, in inner
    response = get_response(request)
  File "/Users/key/PycharmProjects/python_dip_courseproject_django/venv/lib/python3.8/site-packages/django/core/handlers/base.py", line 220, in _get_response
    response = response.render()
  File "/Users/key/PycharmProjects/python_dip_courseproject_django/venv/lib/python3.8/site-packages/django/template/response.py", line 114, in render
    self.content = self.rendered_content
  File "/Users/key/PycharmProjects/python_dip_courseproject_django/venv/lib/python3.8/site-packages/rest_framework/response.py", line 55, in rendered_content
    assert renderer, ".accepted_renderer not set on Response"
AssertionError: .accepted_renderer not set on Response
ERROR 2022-05-13 14:50:51,089 [Thread-1:6165049344] [django.request:241] [log:log_response] [ERROR]- Internal Server Error: /api/
Traceback (most recent call last):
  File "/Users/key/PycharmProjects/python_dip_courseproject_django/venv/lib/python3.8/site-packages/django/core/handlers/exception.py", line 55, in inner
    response = get_response(request)
  File "/Users/key/PycharmProjects/python_dip_courseproject_django/venv/lib/python3.8/site-packages/django/core/handlers/base.py", line 220, in _get_response
    response = response.render()
  File "/Users/key/PycharmProjects/python_dip_courseproject_django/venv/lib/python3.8/site-packages/django/template/response.py", line 114, in render
    self.content = self.rendered_content
  File "/Users/key/PycharmProjects/python_dip_courseproject_django/venv/lib/python3.8/site-packages/rest_framework/response.py", line 55, in rendered_content
    assert renderer, ".accepted_renderer not set on Response"
AssertionError: .accepted_renderer not set on Response
ERROR 2022-05-13 14:50:51,999 [Thread-1:6165049344] [django.request:241] [log:log_response] [ERROR]- Internal Server Error: /api/
Traceback (most recent call last):
  File "/Users/key/PycharmProjects/python_dip_courseproject_django/venv/lib/python3.8/site-packages/django/core/handlers/exception.py", line 55, in inner
    response = get_response(request)
  File "/Users/key/PycharmProjects/python_dip_courseproject_django/venv/lib/python3.8/site-packages/django/core/handlers/base.py", line 220, in _get_response
    response = response.render()
  File "/Users/key/PycharmProjects/python_dip_courseproject_django/venv/lib/python3.8/site-packages/django/template/response.py", line 114, in render
    self.content = self.rendered_content
  File "/Users/key/PycharmProjects/python_dip_courseproject_django/venv/lib/python3.8/site-packages/rest_framework/response.py", line 55, in rendered_content
    assert renderer, ".accepted_renderer not set on Response"
AssertionError: .accepted_renderer not set on Response
ERROR 2022-05-13 14:50:55,943 [Thread-1:6165049344] [django.request:241] [log:log_response] [ERROR]- Internal Server Error: /api/
Traceback (most recent call last):
  File "/Users/key/PycharmProjects/python_dip_courseproject_django/venv/lib/python3.8/site-packages/django/core/handlers/exception.py", line 55, in inner
    response = get_response(request)
  File "/Users/key/PycharmProjects/python_dip_courseproject_django/venv/lib/python3.8/site-packages/django/core/handlers/base.py", line 220, in _get_response
    response = response.render()
  File "/Users/key/PycharmProjects/python_dip_courseproject_django/venv/lib/python3.8/site-packages/django/template/response.py", line 114, in render
    self.content = self.rendered_content
  File "/Users/key/PycharmProjects/python_dip_courseproject_django/venv/lib/python3.8/site-packages/rest_framework/response.py", line 55, in rendered_content
    assert renderer, ".accepted_renderer not set on Response"
AssertionError: .accepted_renderer not set on Response
ERROR 2022-05-13 14:50:57,920 [Thread-1:6165049344] [django.request:241] [log:log_response] [ERROR]- Internal Server Error: /api/
Traceback (most recent call last):
  File "/Users/key/PycharmProjects/python_dip_courseproject_django/venv/lib/python3.8/site-packages/django/core/handlers/exception.py", line 55, in inner
    response = get_response(request)
  File "/Users/key/PycharmProjects/python_dip_courseproject_django/venv/lib/python3.8/site-packages/django/core/handlers/base.py", line 220, in _get_response
    response = response.render()
  File "/Users/key/PycharmProjects/python_dip_courseproject_django/venv/lib/python3.8/site-packages/django/template/response.py", line 114, in render
    self.content = self.rendered_content
  File "/Users/key/PycharmProjects/python_dip_courseproject_django/venv/lib/python3.8/site-packages/rest_framework/response.py", line 55, in rendered_content
    assert renderer, ".accepted_renderer not set on Response"
AssertionError: .accepted_renderer not set on Response
ERROR 2022-05-13 14:51:02,542 [Thread-1:6165049344] [django.request:241] [log:log_response] [ERROR]- Internal Server Error: /api/ImageAPI/
Traceback (most recent call last):
  File "/Users/key/PycharmProjects/python_dip_courseproject_django/venv/lib/python3.8/site-packages/django/core/handlers/exception.py", line 55, in inner
    response = get_response(request)
  File "/Users/key/PycharmProjects/python_dip_courseproject_django/venv/lib/python3.8/site-packages/django/core/handlers/base.py", line 197, in _get_response
    response = wrapped_callback(request, *callback_args, **callback_kwargs)
  File "/Users/key/PycharmProjects/python_dip_courseproject_django/venv/lib/python3.8/site-packages/django/views/decorators/csrf.py", line 54, in wrapped_view
    return view_func(*args, **kwargs)
  File "/Users/key/PycharmProjects/python_dip_courseproject_django/venv/lib/python3.8/site-packages/django/views/generic/base.py", line 84, in view
    return self.dispatch(request, *args, **kwargs)
  File "/Users/key/PycharmProjects/python_dip_courseproject_django/venv/lib/python3.8/site-packages/rest_framework/views.py", line 509, in dispatch
    response = self.handle_exception(exc)
  File "/Users/key/PycharmProjects/python_dip_courseproject_django/venv/lib/python3.8/site-packages/rest_framework/views.py", line 469, in handle_exception
    self.raise_uncaught_exception(exc)
  File "/Users/key/PycharmProjects/python_dip_courseproject_django/venv/lib/python3.8/site-packages/rest_framework/views.py", line 480, in raise_uncaught_exception
    raise exc
  File "/Users/key/PycharmProjects/python_dip_courseproject_django/venv/lib/python3.8/site-packages/rest_framework/views.py", line 506, in dispatch
    response = handler(request, *args, **kwargs)
  File "/Users/key/PycharmProjects/python_dip_courseproject_django/api/views.py", line 26, in get
    images = Image.objects.all()
AttributeError: type object 'Image' has no attribute 'objects'
ERROR 2022-05-13 14:51:28,230 [Thread-1:6165049344] [django.request:241] [log:log_response] [ERROR]- Internal Server Error: /api/
Traceback (most recent call last):
  File "/Users/key/PycharmProjects/python_dip_courseproject_django/venv/lib/python3.8/site-packages/django/core/handlers/exception.py", line 55, in inner
    response = get_response(request)
  File "/Users/key/PycharmProjects/python_dip_courseproject_django/venv/lib/python3.8/site-packages/django/core/handlers/base.py", line 220, in _get_response
    response = response.render()
  File "/Users/key/PycharmProjects/python_dip_courseproject_django/venv/lib/python3.8/site-packages/django/template/response.py", line 114, in render
    self.content = self.rendered_content
  File "/Users/key/PycharmProjects/python_dip_courseproject_django/venv/lib/python3.8/site-packages/rest_framework/response.py", line 55, in rendered_content
    assert renderer, ".accepted_renderer not set on Response"
AssertionError: .accepted_renderer not set on Response
ERROR 2022-05-13 14:51:30,353 [Thread-1:6165049344] [django.request:241] [log:log_response] [ERROR]- Internal Server Error: /api/
Traceback (most recent call last):
  File "/Users/key/PycharmProjects/python_dip_courseproject_django/venv/lib/python3.8/site-packages/django/core/handlers/exception.py", line 55, in inner
    response = get_response(request)
  File "/Users/key/PycharmProjects/python_dip_courseproject_django/venv/lib/python3.8/site-packages/django/core/handlers/base.py", line 220, in _get_response
    response = response.render()
  File "/Users/key/PycharmProjects/python_dip_courseproject_django/venv/lib/python3.8/site-packages/django/template/response.py", line 114, in render
    self.content = self.rendered_content
  File "/Users/key/PycharmProjects/python_dip_courseproject_django/venv/lib/python3.8/site-packages/rest_framework/response.py", line 55, in rendered_content
    assert renderer, ".accepted_renderer not set on Response"
AssertionError: .accepted_renderer not set on Response
ERROR 2022-05-13 14:51:32,276 [Thread-1:6165049344] [django.request:241] [log:log_response] [ERROR]- Internal Server Error: /api/
Traceback (most recent call last):
  File "/Users/key/PycharmProjects/python_dip_courseproject_django/venv/lib/python3.8/site-packages/django/core/handlers/exception.py", line 55, in inner
    response = get_response(request)
  File "/Users/key/PycharmProjects/python_dip_courseproject_django/venv/lib/python3.8/site-packages/django/core/handlers/base.py", line 220, in _get_response
    response = response.render()
  File "/Users/key/PycharmProjects/python_dip_courseproject_django/venv/lib/python3.8/site-packages/django/template/response.py", line 114, in render
    self.content = self.rendered_content
  File "/Users/key/PycharmProjects/python_dip_courseproject_django/venv/lib/python3.8/site-packages/rest_framework/response.py", line 55, in rendered_content
    assert renderer, ".accepted_renderer not set on Response"
AssertionError: .accepted_renderer not set on Response
ERROR 2022-05-13 14:52:55,750 [Thread-1:6155661312] [django.request:241] [log:log_response] [ERROR]- Internal Server Error: /api/
Traceback (most recent call last):
  File "/Users/key/PycharmProjects/python_dip_courseproject_django/venv/lib/python3.8/site-packages/django/core/handlers/exception.py", line 55, in inner
    response = get_response(request)
  File "/Users/key/PycharmProjects/python_dip_courseproject_django/venv/lib/python3.8/site-packages/django/core/handlers/base.py", line 220, in _get_response
    response = response.render()
  File "/Users/key/PycharmProjects/python_dip_courseproject_django/venv/lib/python3.8/site-packages/django/template/response.py", line 114, in render
    self.content = self.rendered_content
  File "/Users/key/PycharmProjects/python_dip_courseproject_django/venv/lib/python3.8/site-packages/rest_framework/response.py", line 55, in rendered_content
    assert renderer, ".accepted_renderer not set on Response"
AssertionError: .accepted_renderer not set on Response
ERROR 2022-05-13 14:53:23,408 [Thread-1:6155661312] [django.request:241] [log:log_response] [ERROR]- Internal Server Error: /api/
Traceback (most recent call last):
  File "/Users/key/PycharmProjects/python_dip_courseproject_django/venv/lib/python3.8/site-packages/django/core/handlers/exception.py", line 55, in inner
    response = get_response(request)
  File "/Users/key/PycharmProjects/python_dip_courseproject_django/venv/lib/python3.8/site-packages/django/core/handlers/base.py", line 220, in _get_response
    response = response.render()
  File "/Users/key/PycharmProjects/python_dip_courseproject_django/venv/lib/python3.8/site-packages/django/template/response.py", line 114, in render
    self.content = self.rendered_content
  File "/Users/key/PycharmProjects/python_dip_courseproject_django/venv/lib/python3.8/site-packages/rest_framework/response.py", line 55, in rendered_content
    assert renderer, ".accepted_renderer not set on Response"
AssertionError: .accepted_renderer not set on Response
ERROR 2022-05-13 14:56:47,016 [Thread-1:6160658432] [django.request:241] [log:log_response] [ERROR]- Internal Server Error: /api/
Traceback (most recent call last):
  File "/Users/key/PycharmProjects/python_dip_courseproject_django/venv/lib/python3.8/site-packages/django/core/handlers/exception.py", line 55, in inner
    response = get_response(request)
  File "/Users/key/PycharmProjects/python_dip_courseproject_django/venv/lib/python3.8/site-packages/django/core/handlers/base.py", line 220, in _get_response
    response = response.render()
  File "/Users/key/PycharmProjects/python_dip_courseproject_django/venv/lib/python3.8/site-packages/django/template/response.py", line 114, in render
    self.content = self.rendered_content
  File "/Users/key/PycharmProjects/python_dip_courseproject_django/venv/lib/python3.8/site-packages/rest_framework/response.py", line 55, in rendered_content
    assert renderer, ".accepted_renderer not set on Response"
AssertionError: .accepted_renderer not set on Response
ERROR 2022-05-13 14:57:05,181 [Thread-1:6191607808] [django.request:241] [log:log_response] [ERROR]- Internal Server Error: /api/
Traceback (most recent call last):
  File "/Users/key/PycharmProjects/python_dip_courseproject_django/venv/lib/python3.8/site-packages/django/core/handlers/exception.py", line 55, in inner
    response = get_response(request)
  File "/Users/key/PycharmProjects/python_dip_courseproject_django/venv/lib/python3.8/site-packages/django/core/handlers/base.py", line 220, in _get_response
    response = response.render()
  File "/Users/key/PycharmProjects/python_dip_courseproject_django/venv/lib/python3.8/site-packages/django/template/response.py", line 114, in render
    self.content = self.rendered_content
  File "/Users/key/PycharmProjects/python_dip_courseproject_django/venv/lib/python3.8/site-packages/rest_framework/response.py", line 55, in rendered_content
    assert renderer, ".accepted_renderer not set on Response"
AssertionError: .accepted_renderer not set on Response
ERROR 2022-05-13 14:57:33,238 [Thread-1:6163001344] [django.request:241] [log:log_response] [ERROR]- Internal Server Error: /api/
Traceback (most recent call last):
  File "/Users/key/PycharmProjects/python_dip_courseproject_django/venv/lib/python3.8/site-packages/django/core/handlers/exception.py", line 55, in inner
    response = get_response(request)
  File "/Users/key/PycharmProjects/python_dip_courseproject_django/venv/lib/python3.8/site-packages/django/core/handlers/base.py", line 204, in _get_response
    self.check_response(response, callback)
  File "/Users/key/PycharmProjects/python_dip_courseproject_django/venv/lib/python3.8/site-packages/django/core/handlers/base.py", line 332, in check_response
    raise ValueError(
ValueError: The view api.views.index didn't return an HttpResponse object. It returned None instead.
ERROR 2022-05-13 15:11:55,823 [Thread-1:6126776320] [django.request:241] [log:log_response] [ERROR]- Internal Server Error: /api/ImageGetAll/
Traceback (most recent call last):
  File "/Users/key/PycharmProjects/python_dip_courseproject_django/venv/lib/python3.8/site-packages/django/core/handlers/exception.py", line 55, in inner
    response = get_response(request)
  File "/Users/key/PycharmProjects/python_dip_courseproject_django/venv/lib/python3.8/site-packages/django/core/handlers/base.py", line 197, in _get_response
    response = wrapped_callback(request, *callback_args, **callback_kwargs)
  File "/Users/key/PycharmProjects/python_dip_courseproject_django/venv/lib/python3.8/site-packages/django/views/decorators/csrf.py", line 54, in wrapped_view
    return view_func(*args, **kwargs)
  File "/Users/key/PycharmProjects/python_dip_courseproject_django/venv/lib/python3.8/site-packages/django/views/generic/base.py", line 84, in view
    return self.dispatch(request, *args, **kwargs)
  File "/Users/key/PycharmProjects/python_dip_courseproject_django/venv/lib/python3.8/site-packages/rest_framework/views.py", line 509, in dispatch
    response = self.handle_exception(exc)
  File "/Users/key/PycharmProjects/python_dip_courseproject_django/venv/lib/python3.8/site-packages/rest_framework/views.py", line 469, in handle_exception
    self.raise_uncaught_exception(exc)
  File "/Users/key/PycharmProjects/python_dip_courseproject_django/venv/lib/python3.8/site-packages/rest_framework/views.py", line 480, in raise_uncaught_exception
    raise exc
  File "/Users/key/PycharmProjects/python_dip_courseproject_django/venv/lib/python3.8/site-packages/rest_framework/views.py", line 506, in dispatch
    response = handler(request, *args, **kwargs)
  File "/Users/key/PycharmProjects/python_dip_courseproject_django/api/views.py", line 25, in get
    images = Image.objects.get(pk=request.query_params.get('id'))
  File "/Users/key/PycharmProjects/python_dip_courseproject_django/venv/lib/python3.8/site-packages/django/db/models/manager.py", line 85, in manager_method
    return getattr(self.get_queryset(), name)(*args, **kwargs)
  File "/Users/key/PycharmProjects/python_dip_courseproject_django/venv/lib/python3.8/site-packages/django/db/models/query.py", line 496, in get
    raise self.model.DoesNotExist(
api.models.Image.DoesNotExist: Image matching query does not exist.
WARNING 2022-05-13 15:12:01,570 [Thread-1:6126776320] [django.request:241] [log:log_response] [WARNING]- Not Found: /api/ImageGetAll/1
ERROR 2022-05-13 15:12:15,870 [Thread-1:6126776320] [django.request:241] [log:log_response] [ERROR]- Internal Server Error: /api/ImageGetAll/
Traceback (most recent call last):
  File "/Users/key/PycharmProjects/python_dip_courseproject_django/venv/lib/python3.8/site-packages/django/core/handlers/exception.py", line 55, in inner
    response = get_response(request)
  File "/Users/key/PycharmProjects/python_dip_courseproject_django/venv/lib/python3.8/site-packages/django/core/handlers/base.py", line 197, in _get_response
    response = wrapped_callback(request, *callback_args, **callback_kwargs)
  File "/Users/key/PycharmProjects/python_dip_courseproject_django/venv/lib/python3.8/site-packages/django/views/decorators/csrf.py", line 54, in wrapped_view
    return view_func(*args, **kwargs)
  File "/Users/key/PycharmProjects/python_dip_courseproject_django/venv/lib/python3.8/site-packages/django/views/generic/base.py", line 84, in view
    return self.dispatch(request, *args, **kwargs)
  File "/Users/key/PycharmProjects/python_dip_courseproject_django/venv/lib/python3.8/site-packages/rest_framework/views.py", line 509, in dispatch
    response = self.handle_exception(exc)
  File "/Users/key/PycharmProjects/python_dip_courseproject_django/venv/lib/python3.8/site-packages/rest_framework/views.py", line 469, in handle_exception
    self.raise_uncaught_exception(exc)
  File "/Users/key/PycharmProjects/python_dip_courseproject_django/venv/lib/python3.8/site-packages/rest_framework/views.py", line 480, in raise_uncaught_exception
    raise exc
  File "/Users/key/PycharmProjects/python_dip_courseproject_django/venv/lib/python3.8/site-packages/rest_framework/views.py", line 506, in dispatch
    response = handler(request, *args, **kwargs)
  File "/Users/key/PycharmProjects/python_dip_courseproject_django/api/views.py", line 27, in get
    return success(serializer.data)
  File "/Users/key/PycharmProjects/python_dip_courseproject_django/venv/lib/python3.8/site-packages/rest_framework/serializers.py", line 768, in data
    ret = super().data
  File "/Users/key/PycharmProjects/python_dip_courseproject_django/venv/lib/python3.8/site-packages/rest_framework/serializers.py", line 253, in data
    self._data = self.to_representation(self.instance)
  File "/Users/key/PycharmProjects/python_dip_courseproject_django/venv/lib/python3.8/site-packages/rest_framework/serializers.py", line 686, in to_representation
    return [
TypeError: 'Image' object is not iterable
ERROR 2022-05-13 15:12:23,938 [Thread-1:6126776320] [django.request:241] [log:log_response] [ERROR]- Internal Server Error: /api/ImageGetAll/
Traceback (most recent call last):
  File "/Users/key/PycharmProjects/python_dip_courseproject_django/venv/lib/python3.8/site-packages/django/core/handlers/exception.py", line 55, in inner
    response = get_response(request)
  File "/Users/key/PycharmProjects/python_dip_courseproject_django/venv/lib/python3.8/site-packages/django/core/handlers/base.py", line 197, in _get_response
    response = wrapped_callback(request, *callback_args, **callback_kwargs)
  File "/Users/key/PycharmProjects/python_dip_courseproject_django/venv/lib/python3.8/site-packages/django/views/decorators/csrf.py", line 54, in wrapped_view
    return view_func(*args, **kwargs)
  File "/Users/key/PycharmProjects/python_dip_courseproject_django/venv/lib/python3.8/site-packages/django/views/generic/base.py", line 84, in view
    return self.dispatch(request, *args, **kwargs)
  File "/Users/key/PycharmProjects/python_dip_courseproject_django/venv/lib/python3.8/site-packages/rest_framework/views.py", line 509, in dispatch
    response = self.handle_exception(exc)
  File "/Users/key/PycharmProjects/python_dip_courseproject_django/venv/lib/python3.8/site-packages/rest_framework/views.py", line 469, in handle_exception
    self.raise_uncaught_exception(exc)
  File "/Users/key/PycharmProjects/python_dip_courseproject_django/venv/lib/python3.8/site-packages/rest_framework/views.py", line 480, in raise_uncaught_exception
    raise exc
  File "/Users/key/PycharmProjects/python_dip_courseproject_django/venv/lib/python3.8/site-packages/rest_framework/views.py", line 506, in dispatch
    response = handler(request, *args, **kwargs)
  File "/Users/key/PycharmProjects/python_dip_courseproject_django/api/views.py", line 27, in get
    return success(serializer.data)
  File "/Users/key/PycharmProjects/python_dip_courseproject_django/venv/lib/python3.8/site-packages/rest_framework/serializers.py", line 768, in data
    ret = super().data
  File "/Users/key/PycharmProjects/python_dip_courseproject_django/venv/lib/python3.8/site-packages/rest_framework/serializers.py", line 253, in data
    self._data = self.to_representation(self.instance)
  File "/Users/key/PycharmProjects/python_dip_courseproject_django/venv/lib/python3.8/site-packages/rest_framework/serializers.py", line 686, in to_representation
    return [
TypeError: 'Image' object is not iterable
ERROR 2022-05-13 15:12:33,476 [Thread-1:6201307136] [django.request:241] [log:log_response] [ERROR]- Internal Server Error: /api/ImageGetAll/
Traceback (most recent call last):
  File "/Users/key/PycharmProjects/python_dip_courseproject_django/venv/lib/python3.8/site-packages/django/core/handlers/exception.py", line 55, in inner
    response = get_response(request)
  File "/Users/key/PycharmProjects/python_dip_courseproject_django/venv/lib/python3.8/site-packages/django/core/handlers/base.py", line 197, in _get_response
    response = wrapped_callback(request, *callback_args, **callback_kwargs)
  File "/Users/key/PycharmProjects/python_dip_courseproject_django/venv/lib/python3.8/site-packages/django/views/decorators/csrf.py", line 54, in wrapped_view
    return view_func(*args, **kwargs)
  File "/Users/key/PycharmProjects/python_dip_courseproject_django/venv/lib/python3.8/site-packages/django/views/generic/base.py", line 84, in view
    return self.dispatch(request, *args, **kwargs)
  File "/Users/key/PycharmProjects/python_dip_courseproject_django/venv/lib/python3.8/site-packages/rest_framework/views.py", line 509, in dispatch
    response = self.handle_exception(exc)
  File "/Users/key/PycharmProjects/python_dip_courseproject_django/venv/lib/python3.8/site-packages/rest_framework/views.py", line 469, in handle_exception
    self.raise_uncaught_exception(exc)
  File "/Users/key/PycharmProjects/python_dip_courseproject_django/venv/lib/python3.8/site-packages/rest_framework/views.py", line 480, in raise_uncaught_exception
    raise exc
  File "/Users/key/PycharmProjects/python_dip_courseproject_django/venv/lib/python3.8/site-packages/rest_framework/views.py", line 506, in dispatch
    response = handler(request, *args, **kwargs)
  File "/Users/key/PycharmProjects/python_dip_courseproject_django/api/views.py", line 27, in get
    return success(serializer.data)
  File "/Users/key/PycharmProjects/python_dip_courseproject_django/venv/lib/python3.8/site-packages/rest_framework/serializers.py", line 768, in data
    ret = super().data
  File "/Users/key/PycharmProjects/python_dip_courseproject_django/venv/lib/python3.8/site-packages/rest_framework/serializers.py", line 253, in data
    self._data = self.to_representation(self.instance)
  File "/Users/key/PycharmProjects/python_dip_courseproject_django/venv/lib/python3.8/site-packages/rest_framework/serializers.py", line 686, in to_representation
    return [
TypeError: 'Image' object is not iterable
WARNING 2022-05-15 12:36:30,129 [Thread-1:6196310016] [django.request:241] [log:log_response] [WARNING]- Not Found: /
WARNING 2022-05-15 12:36:30,131 [Thread-2:6213136384] [django.request:241] [log:log_response] [WARNING]- Not Found: /
WARNING 2022-05-15 12:36:30,265 [Thread-2:6213136384] [django.request:241] [log:log_response] [WARNING]- Not Found: /favicon.ico
WARNING 2022-05-15 12:36:36,545 [Thread-2:6213136384] [django.request:241] [log:log_response] [WARNING]- Not Found: /ImageSet/
WARNING 2022-05-15 12:36:45,317 [Thread-2:6213136384] [django.request:241] [log:log_response] [WARNING]- Not Found: /api/ImageSet/get/1
ERROR 2022-05-15 12:36:49,511 [Thread-2:6213136384] [django.request:241] [log:log_response] [ERROR]- Internal Server Error: /api/ImageSet/1/
Traceback (most recent call last):
  File "/Users/key/PycharmProjects/python_dip_courseproject_django/venv/lib/python3.8/site-packages/django/core/handlers/exception.py", line 55, in inner
    response = get_response(request)
  File "/Users/key/PycharmProjects/python_dip_courseproject_django/venv/lib/python3.8/site-packages/django/core/handlers/base.py", line 197, in _get_response
    response = wrapped_callback(request, *callback_args, **callback_kwargs)
  File "/Users/key/PycharmProjects/python_dip_courseproject_django/venv/lib/python3.8/site-packages/django/views/decorators/csrf.py", line 54, in wrapped_view
    return view_func(*args, **kwargs)
  File "/Users/key/PycharmProjects/python_dip_courseproject_django/venv/lib/python3.8/site-packages/rest_framework/viewsets.py", line 125, in view
    return self.dispatch(request, *args, **kwargs)
  File "/Users/key/PycharmProjects/python_dip_courseproject_django/venv/lib/python3.8/site-packages/rest_framework/views.py", line 509, in dispatch
    response = self.handle_exception(exc)
  File "/Users/key/PycharmProjects/python_dip_courseproject_django/venv/lib/python3.8/site-packages/rest_framework/views.py", line 469, in handle_exception
    self.raise_uncaught_exception(exc)
  File "/Users/key/PycharmProjects/python_dip_courseproject_django/venv/lib/python3.8/site-packages/rest_framework/views.py", line 480, in raise_uncaught_exception
    raise exc
  File "/Users/key/PycharmProjects/python_dip_courseproject_django/venv/lib/python3.8/site-packages/rest_framework/views.py", line 506, in dispatch
    response = handler(request, *args, **kwargs)
  File "/Users/key/PycharmProjects/python_dip_courseproject_django/api/views.py", line 22, in retrieve
    instance = self.get_object(id=kwargs['id'])
KeyError: 'id'
ERROR 2022-05-15 12:37:15,431 [Thread-1:6159609856] [django.request:241] [log:log_response] [ERROR]- Internal Server Error: /api/ImageSet/1/
Traceback (most recent call last):
  File "/Users/key/PycharmProjects/python_dip_courseproject_django/venv/lib/python3.8/site-packages/django/core/handlers/exception.py", line 55, in inner
    response = get_response(request)
  File "/Users/key/PycharmProjects/python_dip_courseproject_django/venv/lib/python3.8/site-packages/django/core/handlers/base.py", line 220, in _get_response
    response = response.render()
  File "/Users/key/PycharmProjects/python_dip_courseproject_django/venv/lib/python3.8/site-packages/django/template/response.py", line 114, in render
    self.content = self.rendered_content
  File "/Users/key/PycharmProjects/python_dip_courseproject_django/venv/lib/python3.8/site-packages/rest_framework/response.py", line 70, in rendered_content
    ret = renderer.render(self.data, accepted_media_type, context)
  File "/Users/key/PycharmProjects/python_dip_courseproject_django/venv/lib/python3.8/site-packages/rest_framework/renderers.py", line 724, in render
    context = self.get_context(data, accepted_media_type, renderer_context)
  File "/Users/key/PycharmProjects/python_dip_courseproject_django/venv/lib/python3.8/site-packages/rest_framework/renderers.py", line 680, in get_context
    'content': self.get_content(renderer, data, accepted_media_type, renderer_context),
  File "/Users/key/PycharmProjects/python_dip_courseproject_django/venv/lib/python3.8/site-packages/rest_framework/renderers.py", line 413, in get_content
    content = renderer.render(data, accepted_media_type, renderer_context)
  File "/Users/key/PycharmProjects/python_dip_courseproject_django/venv/lib/python3.8/site-packages/rest_framework/renderers.py", line 100, in render
    ret = json.dumps(
  File "/Users/key/PycharmProjects/python_dip_courseproject_django/venv/lib/python3.8/site-packages/rest_framework/utils/json.py", line 25, in dumps
    return json.dumps(*args, **kwargs)
  File "/Library/Developer/CommandLineTools/Library/Frameworks/Python3.framework/Versions/3.8/lib/python3.8/json/__init__.py", line 234, in dumps
    return cls(
  File "/Library/Developer/CommandLineTools/Library/Frameworks/Python3.framework/Versions/3.8/lib/python3.8/json/encoder.py", line 201, in encode
    chunks = list(chunks)
  File "/Library/Developer/CommandLineTools/Library/Frameworks/Python3.framework/Versions/3.8/lib/python3.8/json/encoder.py", line 431, in _iterencode
    yield from _iterencode_dict(o, _current_indent_level)
  File "/Library/Developer/CommandLineTools/Library/Frameworks/Python3.framework/Versions/3.8/lib/python3.8/json/encoder.py", line 405, in _iterencode_dict
    yield from chunks
  File "/Library/Developer/CommandLineTools/Library/Frameworks/Python3.framework/Versions/3.8/lib/python3.8/json/encoder.py", line 438, in _iterencode
    o = _default(o)
  File "/Users/key/PycharmProjects/python_dip_courseproject_django/venv/lib/python3.8/site-packages/rest_framework/utils/encoders.py", line 66, in default
    return tuple(item for item in obj)
TypeError: 'Request' object is not iterable
ERROR 2022-05-15 12:37:15,817 [Thread-1:6159609856] [django.request:241] [log:log_response] [ERROR]- Internal Server Error: /api/ImageSet/1/
Traceback (most recent call last):
  File "/Users/key/PycharmProjects/python_dip_courseproject_django/venv/lib/python3.8/site-packages/django/core/handlers/exception.py", line 55, in inner
    response = get_response(request)
  File "/Users/key/PycharmProjects/python_dip_courseproject_django/venv/lib/python3.8/site-packages/django/core/handlers/base.py", line 220, in _get_response
    response = response.render()
  File "/Users/key/PycharmProjects/python_dip_courseproject_django/venv/lib/python3.8/site-packages/django/template/response.py", line 114, in render
    self.content = self.rendered_content
  File "/Users/key/PycharmProjects/python_dip_courseproject_django/venv/lib/python3.8/site-packages/rest_framework/response.py", line 70, in rendered_content
    ret = renderer.render(self.data, accepted_media_type, context)
  File "/Users/key/PycharmProjects/python_dip_courseproject_django/venv/lib/python3.8/site-packages/rest_framework/renderers.py", line 724, in render
    context = self.get_context(data, accepted_media_type, renderer_context)
  File "/Users/key/PycharmProjects/python_dip_courseproject_django/venv/lib/python3.8/site-packages/rest_framework/renderers.py", line 680, in get_context
    'content': self.get_content(renderer, data, accepted_media_type, renderer_context),
  File "/Users/key/PycharmProjects/python_dip_courseproject_django/venv/lib/python3.8/site-packages/rest_framework/renderers.py", line 413, in get_content
    content = renderer.render(data, accepted_media_type, renderer_context)
  File "/Users/key/PycharmProjects/python_dip_courseproject_django/venv/lib/python3.8/site-packages/rest_framework/renderers.py", line 100, in render
    ret = json.dumps(
  File "/Users/key/PycharmProjects/python_dip_courseproject_django/venv/lib/python3.8/site-packages/rest_framework/utils/json.py", line 25, in dumps
    return json.dumps(*args, **kwargs)
  File "/Library/Developer/CommandLineTools/Library/Frameworks/Python3.framework/Versions/3.8/lib/python3.8/json/__init__.py", line 234, in dumps
    return cls(
  File "/Library/Developer/CommandLineTools/Library/Frameworks/Python3.framework/Versions/3.8/lib/python3.8/json/encoder.py", line 201, in encode
    chunks = list(chunks)
  File "/Library/Developer/CommandLineTools/Library/Frameworks/Python3.framework/Versions/3.8/lib/python3.8/json/encoder.py", line 431, in _iterencode
    yield from _iterencode_dict(o, _current_indent_level)
  File "/Library/Developer/CommandLineTools/Library/Frameworks/Python3.framework/Versions/3.8/lib/python3.8/json/encoder.py", line 405, in _iterencode_dict
    yield from chunks
  File "/Library/Developer/CommandLineTools/Library/Frameworks/Python3.framework/Versions/3.8/lib/python3.8/json/encoder.py", line 438, in _iterencode
    o = _default(o)
  File "/Users/key/PycharmProjects/python_dip_courseproject_django/venv/lib/python3.8/site-packages/rest_framework/utils/encoders.py", line 66, in default
    return tuple(item for item in obj)
TypeError: 'Request' object is not iterable
ERROR 2022-05-15 12:37:58,946 [Thread-1:6124564480] [django.request:241] [log:log_response] [ERROR]- Internal Server Error: /api/ImageSet/1/
Traceback (most recent call last):
  File "/Users/key/PycharmProjects/python_dip_courseproject_django/venv/lib/python3.8/site-packages/django/core/handlers/exception.py", line 55, in inner
    response = get_response(request)
  File "/Users/key/PycharmProjects/python_dip_courseproject_django/venv/lib/python3.8/site-packages/django/core/handlers/base.py", line 197, in _get_response
    response = wrapped_callback(request, *callback_args, **callback_kwargs)
  File "/Users/key/PycharmProjects/python_dip_courseproject_django/venv/lib/python3.8/site-packages/django/views/decorators/csrf.py", line 54, in wrapped_view
    return view_func(*args, **kwargs)
  File "/Users/key/PycharmProjects/python_dip_courseproject_django/venv/lib/python3.8/site-packages/rest_framework/viewsets.py", line 125, in view
    return self.dispatch(request, *args, **kwargs)
  File "/Users/key/PycharmProjects/python_dip_courseproject_django/venv/lib/python3.8/site-packages/rest_framework/views.py", line 509, in dispatch
    response = self.handle_exception(exc)
  File "/Users/key/PycharmProjects/python_dip_courseproject_django/venv/lib/python3.8/site-packages/rest_framework/views.py", line 469, in handle_exception
    self.raise_uncaught_exception(exc)
  File "/Users/key/PycharmProjects/python_dip_courseproject_django/venv/lib/python3.8/site-packages/rest_framework/views.py", line 480, in raise_uncaught_exception
    raise exc
  File "/Users/key/PycharmProjects/python_dip_courseproject_django/venv/lib/python3.8/site-packages/rest_framework/views.py", line 506, in dispatch
    response = handler(request, *args, **kwargs)
  File "/Users/key/PycharmProjects/python_dip_courseproject_django/api/views.py", line 22, in retrieve
    instance = self.get_object(request.query_params.get('id'))
TypeError: get_object() takes 1 positional argument but 2 were given
ERROR 2022-05-15 12:38:20,232 [Thread-1:6124564480] [django.request:241] [log:log_response] [ERROR]- Internal Server Error: /api/ImageSet/1/
Traceback (most recent call last):
  File "/Users/key/PycharmProjects/python_dip_courseproject_django/venv/lib/python3.8/site-packages/django/core/handlers/exception.py", line 55, in inner
    response = get_response(request)
  File "/Users/key/PycharmProjects/python_dip_courseproject_django/venv/lib/python3.8/site-packages/django/core/handlers/base.py", line 197, in _get_response
    response = wrapped_callback(request, *callback_args, **callback_kwargs)
  File "/Users/key/PycharmProjects/python_dip_courseproject_django/venv/lib/python3.8/site-packages/django/views/decorators/csrf.py", line 54, in wrapped_view
    return view_func(*args, **kwargs)
  File "/Users/key/PycharmProjects/python_dip_courseproject_django/venv/lib/python3.8/site-packages/rest_framework/viewsets.py", line 125, in view
    return self.dispatch(request, *args, **kwargs)
  File "/Users/key/PycharmProjects/python_dip_courseproject_django/venv/lib/python3.8/site-packages/rest_framework/views.py", line 509, in dispatch
    response = self.handle_exception(exc)
  File "/Users/key/PycharmProjects/python_dip_courseproject_django/venv/lib/python3.8/site-packages/rest_framework/views.py", line 469, in handle_exception
    self.raise_uncaught_exception(exc)
  File "/Users/key/PycharmProjects/python_dip_courseproject_django/venv/lib/python3.8/site-packages/rest_framework/views.py", line 480, in raise_uncaught_exception
    raise exc
  File "/Users/key/PycharmProjects/python_dip_courseproject_django/venv/lib/python3.8/site-packages/rest_framework/views.py", line 506, in dispatch
    response = handler(request, *args, **kwargs)
  File "/Users/key/PycharmProjects/python_dip_courseproject_django/api/views.py", line 22, in retrieve
    instance = self.get_object(request.query_params.get('id'))
TypeError: get_object() takes 1 positional argument but 2 were given
ERROR 2022-05-15 12:39:11,355 [Thread-5:6188724224] [django.request:241] [log:log_response] [ERROR]- Internal Server Error: /api/ImageSet/1/
Traceback (most recent call last):
  File "/Users/key/PycharmProjects/python_dip_courseproject_django/venv/lib/python3.8/site-packages/django/core/handlers/exception.py", line 55, in inner
    response = get_response(request)
  File "/Users/key/PycharmProjects/python_dip_courseproject_django/venv/lib/python3.8/site-packages/django/core/handlers/base.py", line 197, in _get_response
    response = wrapped_callback(request, *callback_args, **callback_kwargs)
  File "/Users/key/PycharmProjects/python_dip_courseproject_django/venv/lib/python3.8/site-packages/django/views/decorators/csrf.py", line 54, in wrapped_view
    return view_func(*args, **kwargs)
  File "/Users/key/PycharmProjects/python_dip_courseproject_django/venv/lib/python3.8/site-packages/rest_framework/viewsets.py", line 125, in view
    return self.dispatch(request, *args, **kwargs)
  File "/Users/key/PycharmProjects/python_dip_courseproject_django/venv/lib/python3.8/site-packages/rest_framework/views.py", line 509, in dispatch
    response = self.handle_exception(exc)
  File "/Users/key/PycharmProjects/python_dip_courseproject_django/venv/lib/python3.8/site-packages/rest_framework/views.py", line 469, in handle_exception
    self.raise_uncaught_exception(exc)
  File "/Users/key/PycharmProjects/python_dip_courseproject_django/venv/lib/python3.8/site-packages/rest_framework/views.py", line 480, in raise_uncaught_exception
    raise exc
  File "/Users/key/PycharmProjects/python_dip_courseproject_django/venv/lib/python3.8/site-packages/rest_framework/views.py", line 506, in dispatch
    response = handler(request, *args, **kwargs)
  File "/Users/key/PycharmProjects/python_dip_courseproject_django/api/views.py", line 23, in retrieve
    instance = self.get_object(kwargs['pk'])
TypeError: get_object() takes 1 positional argument but 2 were given
ERROR 2022-05-15 12:39:12,053 [Thread-5:6188724224] [django.request:241] [log:log_response] [ERROR]- Internal Server Error: /api/ImageSet/1/
Traceback (most recent call last):
  File "/Users/key/PycharmProjects/python_dip_courseproject_django/venv/lib/python3.8/site-packages/django/core/handlers/exception.py", line 55, in inner
    response = get_response(request)
  File "/Users/key/PycharmProjects/python_dip_courseproject_django/venv/lib/python3.8/site-packages/django/core/handlers/base.py", line 197, in _get_response
    response = wrapped_callback(request, *callback_args, **callback_kwargs)
  File "/Users/key/PycharmProjects/python_dip_courseproject_django/venv/lib/python3.8/site-packages/django/views/decorators/csrf.py", line 54, in wrapped_view
    return view_func(*args, **kwargs)
  File "/Users/key/PycharmProjects/python_dip_courseproject_django/venv/lib/python3.8/site-packages/rest_framework/viewsets.py", line 125, in view
    return self.dispatch(request, *args, **kwargs)
  File "/Users/key/PycharmProjects/python_dip_courseproject_django/venv/lib/python3.8/site-packages/rest_framework/views.py", line 509, in dispatch
    response = self.handle_exception(exc)
  File "/Users/key/PycharmProjects/python_dip_courseproject_django/venv/lib/python3.8/site-packages/rest_framework/views.py", line 469, in handle_exception
    self.raise_uncaught_exception(exc)
  File "/Users/key/PycharmProjects/python_dip_courseproject_django/venv/lib/python3.8/site-packages/rest_framework/views.py", line 480, in raise_uncaught_exception
    raise exc
  File "/Users/key/PycharmProjects/python_dip_courseproject_django/venv/lib/python3.8/site-packages/rest_framework/views.py", line 506, in dispatch
    response = handler(request, *args, **kwargs)
  File "/Users/key/PycharmProjects/python_dip_courseproject_django/api/views.py", line 23, in retrieve
    instance = self.get_object(kwargs['pk'])
TypeError: get_object() takes 1 positional argument but 2 were given
ERROR 2022-05-15 12:39:12,962 [Thread-5:6188724224] [django.request:241] [log:log_response] [ERROR]- Internal Server Error: /api/ImageSet/1/
Traceback (most recent call last):
  File "/Users/key/PycharmProjects/python_dip_courseproject_django/venv/lib/python3.8/site-packages/django/core/handlers/exception.py", line 55, in inner
    response = get_response(request)
  File "/Users/key/PycharmProjects/python_dip_courseproject_django/venv/lib/python3.8/site-packages/django/core/handlers/base.py", line 197, in _get_response
    response = wrapped_callback(request, *callback_args, **callback_kwargs)
  File "/Users/key/PycharmProjects/python_dip_courseproject_django/venv/lib/python3.8/site-packages/django/views/decorators/csrf.py", line 54, in wrapped_view
    return view_func(*args, **kwargs)
  File "/Users/key/PycharmProjects/python_dip_courseproject_django/venv/lib/python3.8/site-packages/rest_framework/viewsets.py", line 125, in view
    return self.dispatch(request, *args, **kwargs)
  File "/Users/key/PycharmProjects/python_dip_courseproject_django/venv/lib/python3.8/site-packages/rest_framework/views.py", line 509, in dispatch
    response = self.handle_exception(exc)
  File "/Users/key/PycharmProjects/python_dip_courseproject_django/venv/lib/python3.8/site-packages/rest_framework/views.py", line 469, in handle_exception
    self.raise_uncaught_exception(exc)
  File "/Users/key/PycharmProjects/python_dip_courseproject_django/venv/lib/python3.8/site-packages/rest_framework/views.py", line 480, in raise_uncaught_exception
    raise exc
  File "/Users/key/PycharmProjects/python_dip_courseproject_django/venv/lib/python3.8/site-packages/rest_framework/views.py", line 506, in dispatch
    response = handler(request, *args, **kwargs)
  File "/Users/key/PycharmProjects/python_dip_courseproject_django/api/views.py", line 23, in retrieve
    instance = self.get_object(kwargs['pk'])
TypeError: get_object() takes 1 positional argument but 2 were given
ERROR 2022-05-15 12:39:16,880 [Thread-1:6122418176] [django.request:241] [log:log_response] [ERROR]- Internal Server Error: /api/ImageSet/1/
Traceback (most recent call last):
  File "/Users/key/PycharmProjects/python_dip_courseproject_django/venv/lib/python3.8/site-packages/django/core/handlers/exception.py", line 55, in inner
    response = get_response(request)
  File "/Users/key/PycharmProjects/python_dip_courseproject_django/venv/lib/python3.8/site-packages/django/core/handlers/base.py", line 197, in _get_response
    response = wrapped_callback(request, *callback_args, **callback_kwargs)
  File "/Users/key/PycharmProjects/python_dip_courseproject_django/venv/lib/python3.8/site-packages/django/views/decorators/csrf.py", line 54, in wrapped_view
    return view_func(*args, **kwargs)
  File "/Users/key/PycharmProjects/python_dip_courseproject_django/venv/lib/python3.8/site-packages/rest_framework/viewsets.py", line 125, in view
    return self.dispatch(request, *args, **kwargs)
  File "/Users/key/PycharmProjects/python_dip_courseproject_django/venv/lib/python3.8/site-packages/rest_framework/views.py", line 509, in dispatch
    response = self.handle_exception(exc)
  File "/Users/key/PycharmProjects/python_dip_courseproject_django/venv/lib/python3.8/site-packages/rest_framework/views.py", line 469, in handle_exception
    self.raise_uncaught_exception(exc)
  File "/Users/key/PycharmProjects/python_dip_courseproject_django/venv/lib/python3.8/site-packages/rest_framework/views.py", line 480, in raise_uncaught_exception
    raise exc
  File "/Users/key/PycharmProjects/python_dip_courseproject_django/venv/lib/python3.8/site-packages/rest_framework/views.py", line 506, in dispatch
    response = handler(request, *args, **kwargs)
  File "/Users/key/PycharmProjects/python_dip_courseproject_django/api/views.py", line 23, in retrieve
    instance = self.get_object(kwargs['pk'])
TypeError: get_object() takes 1 positional argument but 2 were given
ERROR 2022-05-15 12:55:12,990 [Thread-1:6201896960] [django.request:241] [log:log_response] [ERROR]- Internal Server Error: /api/ImageSet/
Traceback (most recent call last):
  File "/Users/key/PycharmProjects/python_dip_courseproject_django/venv/lib/python3.8/site-packages/django/core/handlers/exception.py", line 55, in inner
    response = get_response(request)
  File "/Users/key/PycharmProjects/python_dip_courseproject_django/venv/lib/python3.8/site-packages/django/core/handlers/base.py", line 197, in _get_response
    response = wrapped_callback(request, *callback_args, **callback_kwargs)
  File "/Users/key/PycharmProjects/python_dip_courseproject_django/venv/lib/python3.8/site-packages/django/views/decorators/csrf.py", line 54, in wrapped_view
    return view_func(*args, **kwargs)
  File "/Users/key/PycharmProjects/python_dip_courseproject_django/venv/lib/python3.8/site-packages/rest_framework/viewsets.py", line 125, in view
    return self.dispatch(request, *args, **kwargs)
  File "/Users/key/PycharmProjects/python_dip_courseproject_django/venv/lib/python3.8/site-packages/rest_framework/views.py", line 509, in dispatch
    response = self.handle_exception(exc)
  File "/Users/key/PycharmProjects/python_dip_courseproject_django/venv/lib/python3.8/site-packages/rest_framework/views.py", line 469, in handle_exception
    self.raise_uncaught_exception(exc)
  File "/Users/key/PycharmProjects/python_dip_courseproject_django/venv/lib/python3.8/site-packages/rest_framework/views.py", line 480, in raise_uncaught_exception
    raise exc
  File "/Users/key/PycharmProjects/python_dip_courseproject_django/venv/lib/python3.8/site-packages/rest_framework/views.py", line 506, in dispatch
    response = handler(request, *args, **kwargs)
  File "/Users/key/PycharmProjects/python_dip_courseproject_django/api/views.py", line 37, in create
    return success(serializer.data, headers=headers)
TypeError: success() got an unexpected keyword argument 'headers'
WARNING 2022-05-15 13:30:09,531 [Thread-2:6184644608] [django.request:241] [log:log_response] [WARNING]- Not Found: /images/阿米娅作者未知_hgX3jXK.png
ERROR 2022-05-15 13:36:52,178 [Thread-5:6161788928] [django.request:241] [log:log_response] [ERROR]- Internal Server Error: /api/ImageSet/
Traceback (most recent call last):
  File "/Users/key/PycharmProjects/python_dip_courseproject_django/venv/lib/python3.8/site-packages/django/core/handlers/exception.py", line 55, in inner
    response = get_response(request)
  File "/Users/key/PycharmProjects/python_dip_courseproject_django/venv/lib/python3.8/site-packages/django/core/handlers/base.py", line 197, in _get_response
    response = wrapped_callback(request, *callback_args, **callback_kwargs)
  File "/Users/key/PycharmProjects/python_dip_courseproject_django/venv/lib/python3.8/site-packages/django/views/decorators/csrf.py", line 54, in wrapped_view
    return view_func(*args, **kwargs)
  File "/Users/key/PycharmProjects/python_dip_courseproject_django/venv/lib/python3.8/site-packages/rest_framework/viewsets.py", line 125, in view
    return self.dispatch(request, *args, **kwargs)
  File "/Users/key/PycharmProjects/python_dip_courseproject_django/venv/lib/python3.8/site-packages/rest_framework/views.py", line 509, in dispatch
    response = self.handle_exception(exc)
  File "/Users/key/PycharmProjects/python_dip_courseproject_django/venv/lib/python3.8/site-packages/rest_framework/views.py", line 469, in handle_exception
    self.raise_uncaught_exception(exc)
  File "/Users/key/PycharmProjects/python_dip_courseproject_django/venv/lib/python3.8/site-packages/rest_framework/views.py", line 480, in raise_uncaught_exception
    raise exc
  File "/Users/key/PycharmProjects/python_dip_courseproject_django/venv/lib/python3.8/site-packages/rest_framework/views.py", line 506, in dispatch
    response = handler(request, *args, **kwargs)
  File "/Users/key/PycharmProjects/python_dip_courseproject_django/api/views.py", line 37, in create
    file_one = open(serializer.data['file'], "rb")
FileNotFoundError: [Errno 2] No such file or directory: 'http://127.0.0.1:8000/images/%E9%98%BF%E7%B1%B3%E5%A8%85%E4%BD%9C%E8%80%85%E6%9C%AA%E7%9F%A5_OTr7YXI.png'
WARNING 2022-05-15 13:40:30,364 [Thread-2:6221361152] [django.request:241] [log:log_response] [WARNING]- Not Found: /images/阿米娅作者未知.png
WARNING 2022-05-15 13:41:17,690 [Thread-2:6173683712] [django.request:241] [log:log_response] [WARNING]- Not Found: /images/阿米娅作者未知_0HzVpr2.png
WARNING 2022-05-15 13:50:54,056 [Thread-2:6146338816] [django.request:241] [log:log_response] [WARNING]- Not Found: /media/images/IMG_9634.JPG
WARNING 2022-05-15 14:41:15,368 [Thread-1:6206582784] [django.request:241] [log:log_response] [WARNING]- Not Found: /
WARNING 2022-05-15 14:41:21,170 [Thread-1:6206582784] [django.request:241] [log:log_response] [WARNING]- Not Found: /api/resize/1
WARNING 2022-05-15 14:42:00,660 [Thread-3:6240235520] [django.request:241] [log:log_response] [WARNING]- Method Not Allowed: /api/resize/
WARNING 2022-05-15 14:42:08,811 [Thread-3:6240235520] [django.request:241] [log:log_response] [WARNING]- Method Not Allowed: /api/resize/
WARNING 2022-05-15 14:42:42,932 [Thread-1:6135820288] [django.request:241] [log:log_response] [WARNING]- Method Not Allowed: /api/resize/
ERROR 2022-05-15 14:42:53,742 [Thread-1:6201946112] [django.request:241] [log:log_response] [ERROR]- Internal Server Error: /api/resize/
Traceback (most recent call last):
  File "/Users/key/PycharmProjects/python_dip_courseproject_django/venv/lib/python3.8/site-packages/django/core/handlers/exception.py", line 55, in inner
    response = get_response(request)
  File "/Users/key/PycharmProjects/python_dip_courseproject_django/venv/lib/python3.8/site-packages/django/core/handlers/base.py", line 197, in _get_response
    response = wrapped_callback(request, *callback_args, **callback_kwargs)
  File "/Users/key/PycharmProjects/python_dip_courseproject_django/venv/lib/python3.8/site-packages/django/views/decorators/csrf.py", line 54, in wrapped_view
    return view_func(*args, **kwargs)
  File "/Users/key/PycharmProjects/python_dip_courseproject_django/venv/lib/python3.8/site-packages/django/views/generic/base.py", line 84, in view
    return self.dispatch(request, *args, **kwargs)
  File "/Users/key/PycharmProjects/python_dip_courseproject_django/venv/lib/python3.8/site-packages/rest_framework/views.py", line 509, in dispatch
    response = self.handle_exception(exc)
  File "/Users/key/PycharmProjects/python_dip_courseproject_django/venv/lib/python3.8/site-packages/rest_framework/views.py", line 469, in handle_exception
    self.raise_uncaught_exception(exc)
  File "/Users/key/PycharmProjects/python_dip_courseproject_django/venv/lib/python3.8/site-packages/rest_framework/views.py", line 480, in raise_uncaught_exception
    raise exc
  File "/Users/key/PycharmProjects/python_dip_courseproject_django/venv/lib/python3.8/site-packages/rest_framework/views.py", line 506, in dispatch
    response = handler(request, *args, **kwargs)
  File "/Users/key/PycharmProjects/python_dip_courseproject_django/api/views.py", line 47, in post
    images = Image.objects.get(id=request.data.get('id'))
  File "/Users/key/PycharmProjects/python_dip_courseproject_django/venv/lib/python3.8/site-packages/django/db/models/manager.py", line 85, in manager_method
    return getattr(self.get_queryset(), name)(*args, **kwargs)
  File "/Users/key/PycharmProjects/python_dip_courseproject_django/venv/lib/python3.8/site-packages/django/db/models/query.py", line 496, in get
    raise self.model.DoesNotExist(
api.models.Image.DoesNotExist: Image matching query does not exist.
ERROR 2022-05-15 14:43:39,365 [Thread-1:6201946112] [django.request:241] [log:log_response] [ERROR]- Internal Server Error: /api/resize/
Traceback (most recent call last):
  File "/Users/key/PycharmProjects/python_dip_courseproject_django/venv/lib/python3.8/site-packages/django/core/handlers/exception.py", line 55, in inner
    response = get_response(request)
  File "/Users/key/PycharmProjects/python_dip_courseproject_django/venv/lib/python3.8/site-packages/django/core/handlers/base.py", line 197, in _get_response
    response = wrapped_callback(request, *callback_args, **callback_kwargs)
  File "/Users/key/PycharmProjects/python_dip_courseproject_django/venv/lib/python3.8/site-packages/django/views/decorators/csrf.py", line 54, in wrapped_view
    return view_func(*args, **kwargs)
  File "/Users/key/PycharmProjects/python_dip_courseproject_django/venv/lib/python3.8/site-packages/django/views/generic/base.py", line 84, in view
    return self.dispatch(request, *args, **kwargs)
  File "/Users/key/PycharmProjects/python_dip_courseproject_django/venv/lib/python3.8/site-packages/rest_framework/views.py", line 509, in dispatch
    response = self.handle_exception(exc)
  File "/Users/key/PycharmProjects/python_dip_courseproject_django/venv/lib/python3.8/site-packages/rest_framework/views.py", line 469, in handle_exception
    self.raise_uncaught_exception(exc)
  File "/Users/key/PycharmProjects/python_dip_courseproject_django/venv/lib/python3.8/site-packages/rest_framework/views.py", line 480, in raise_uncaught_exception
    raise exc
  File "/Users/key/PycharmProjects/python_dip_courseproject_django/venv/lib/python3.8/site-packages/rest_framework/views.py", line 506, in dispatch
    response = handler(request, *args, **kwargs)
  File "/Users/key/PycharmProjects/python_dip_courseproject_django/api/views.py", line 47, in post
    images = Image.objects.get(id=request.data.get('id'))
  File "/Users/key/PycharmProjects/python_dip_courseproject_django/venv/lib/python3.8/site-packages/django/db/models/manager.py", line 85, in manager_method
    return getattr(self.get_queryset(), name)(*args, **kwargs)
  File "/Users/key/PycharmProjects/python_dip_courseproject_django/venv/lib/python3.8/site-packages/django/db/models/query.py", line 496, in get
    raise self.model.DoesNotExist(
api.models.Image.DoesNotExist: Image matching query does not exist.
WARNING 2022-05-15 14:43:43,254 [Thread-2:6218772480] [django.request:241] [log:log_response] [WARNING]- Not Found: /api/resize/1
WARNING 2022-05-15 14:43:45,247 [Thread-2:6218772480] [django.request:241] [log:log_response] [WARNING]- Method Not Allowed: /api/resize/
ERROR 2022-05-15 14:43:59,714 [Thread-1:6201946112] [django.request:241] [log:log_response] [ERROR]- Internal Server Error: /api/resize/
Traceback (most recent call last):
  File "/Users/key/PycharmProjects/python_dip_courseproject_django/venv/lib/python3.8/site-packages/django/core/handlers/exception.py", line 55, in inner
    response = get_response(request)
  File "/Users/key/PycharmProjects/python_dip_courseproject_django/venv/lib/python3.8/site-packages/django/core/handlers/base.py", line 197, in _get_response
    response = wrapped_callback(request, *callback_args, **callback_kwargs)
  File "/Users/key/PycharmProjects/python_dip_courseproject_django/venv/lib/python3.8/site-packages/django/views/decorators/csrf.py", line 54, in wrapped_view
    return view_func(*args, **kwargs)
  File "/Users/key/PycharmProjects/python_dip_courseproject_django/venv/lib/python3.8/site-packages/django/views/generic/base.py", line 84, in view
    return self.dispatch(request, *args, **kwargs)
  File "/Users/key/PycharmProjects/python_dip_courseproject_django/venv/lib/python3.8/site-packages/rest_framework/views.py", line 509, in dispatch
    response = self.handle_exception(exc)
  File "/Users/key/PycharmProjects/python_dip_courseproject_django/venv/lib/python3.8/site-packages/rest_framework/views.py", line 469, in handle_exception
    self.raise_uncaught_exception(exc)
  File "/Users/key/PycharmProjects/python_dip_courseproject_django/venv/lib/python3.8/site-packages/rest_framework/views.py", line 480, in raise_uncaught_exception
    raise exc
  File "/Users/key/PycharmProjects/python_dip_courseproject_django/venv/lib/python3.8/site-packages/rest_framework/views.py", line 506, in dispatch
    response = handler(request, *args, **kwargs)
  File "/Users/key/PycharmProjects/python_dip_courseproject_django/api/views.py", line 47, in post
    images = Image.objects.get(id=request.data.get('id'))
  File "/Users/key/PycharmProjects/python_dip_courseproject_django/venv/lib/python3.8/site-packages/django/db/models/manager.py", line 85, in manager_method
    return getattr(self.get_queryset(), name)(*args, **kwargs)
  File "/Users/key/PycharmProjects/python_dip_courseproject_django/venv/lib/python3.8/site-packages/django/db/models/query.py", line 496, in get
    raise self.model.DoesNotExist(
api.models.Image.DoesNotExist: Image matching query does not exist.
ERROR 2022-05-15 14:44:36,651 [Thread-1:6127677440] [django.request:241] [log:log_response] [ERROR]- Internal Server Error: /api/resize/
Traceback (most recent call last):
  File "/Users/key/PycharmProjects/python_dip_courseproject_django/venv/lib/python3.8/site-packages/django/core/handlers/exception.py", line 55, in inner
    response = get_response(request)
  File "/Users/key/PycharmProjects/python_dip_courseproject_django/venv/lib/python3.8/site-packages/django/core/handlers/base.py", line 197, in _get_response
    response = wrapped_callback(request, *callback_args, **callback_kwargs)
  File "/Users/key/PycharmProjects/python_dip_courseproject_django/venv/lib/python3.8/site-packages/django/views/decorators/csrf.py", line 54, in wrapped_view
    return view_func(*args, **kwargs)
  File "/Users/key/PycharmProjects/python_dip_courseproject_django/venv/lib/python3.8/site-packages/django/views/generic/base.py", line 84, in view
    return self.dispatch(request, *args, **kwargs)
  File "/Users/key/PycharmProjects/python_dip_courseproject_django/venv/lib/python3.8/site-packages/rest_framework/views.py", line 509, in dispatch
    response = self.handle_exception(exc)
  File "/Users/key/PycharmProjects/python_dip_courseproject_django/venv/lib/python3.8/site-packages/rest_framework/views.py", line 469, in handle_exception
    self.raise_uncaught_exception(exc)
  File "/Users/key/PycharmProjects/python_dip_courseproject_django/venv/lib/python3.8/site-packages/rest_framework/views.py", line 480, in raise_uncaught_exception
    raise exc
  File "/Users/key/PycharmProjects/python_dip_courseproject_django/venv/lib/python3.8/site-packages/rest_framework/views.py", line 506, in dispatch
    response = handler(request, *args, **kwargs)
  File "/Users/key/PycharmProjects/python_dip_courseproject_django/api/views.py", line 50, in post
    images = Image.objects.get(id=request.data.get('id'))
  File "/Users/key/PycharmProjects/python_dip_courseproject_django/venv/lib/python3.8/site-packages/django/db/models/manager.py", line 85, in manager_method
    return getattr(self.get_queryset(), name)(*args, **kwargs)
  File "/Users/key/PycharmProjects/python_dip_courseproject_django/venv/lib/python3.8/site-packages/django/db/models/query.py", line 496, in get
    raise self.model.DoesNotExist(
api.models.Image.DoesNotExist: Image matching query does not exist.
ERROR 2022-05-15 14:44:51,390 [Thread-1:6209253376] [django.request:241] [log:log_response] [ERROR]- Internal Server Error: /api/resize/
Traceback (most recent call last):
  File "/Users/key/PycharmProjects/python_dip_courseproject_django/venv/lib/python3.8/site-packages/django/core/handlers/exception.py", line 55, in inner
    response = get_response(request)
  File "/Users/key/PycharmProjects/python_dip_courseproject_django/venv/lib/python3.8/site-packages/django/core/handlers/base.py", line 197, in _get_response
    response = wrapped_callback(request, *callback_args, **callback_kwargs)
  File "/Users/key/PycharmProjects/python_dip_courseproject_django/venv/lib/python3.8/site-packages/django/views/decorators/csrf.py", line 54, in wrapped_view
    return view_func(*args, **kwargs)
  File "/Users/key/PycharmProjects/python_dip_courseproject_django/venv/lib/python3.8/site-packages/django/views/generic/base.py", line 84, in view
    return self.dispatch(request, *args, **kwargs)
  File "/Users/key/PycharmProjects/python_dip_courseproject_django/venv/lib/python3.8/site-packages/rest_framework/views.py", line 509, in dispatch
    response = self.handle_exception(exc)
  File "/Users/key/PycharmProjects/python_dip_courseproject_django/venv/lib/python3.8/site-packages/rest_framework/views.py", line 469, in handle_exception
    self.raise_uncaught_exception(exc)
  File "/Users/key/PycharmProjects/python_dip_courseproject_django/venv/lib/python3.8/site-packages/rest_framework/views.py", line 480, in raise_uncaught_exception
    raise exc
  File "/Users/key/PycharmProjects/python_dip_courseproject_django/venv/lib/python3.8/site-packages/rest_framework/views.py", line 506, in dispatch
    response = handler(request, *args, **kwargs)
  File "/Users/key/PycharmProjects/python_dip_courseproject_django/api/views.py", line 51, in post
    images = Image.objects.get(id=request.data.get('id'))
  File "/Users/key/PycharmProjects/python_dip_courseproject_django/venv/lib/python3.8/site-packages/django/db/models/manager.py", line 85, in manager_method
    return getattr(self.get_queryset(), name)(*args, **kwargs)
  File "/Users/key/PycharmProjects/python_dip_courseproject_django/venv/lib/python3.8/site-packages/django/db/models/query.py", line 496, in get
    raise self.model.DoesNotExist(
api.models.Image.DoesNotExist: Image matching query does not exist.
ERROR 2022-05-15 14:46:06,521 [Thread-1:6325039104] [django.request:241] [log:log_response] [ERROR]- Internal Server Error: /api/resize/
Traceback (most recent call last):
  File "/Users/key/PycharmProjects/python_dip_courseproject_django/venv/lib/python3.8/site-packages/django/core/handlers/exception.py", line 55, in inner
    response = get_response(request)
  File "/Users/key/PycharmProjects/python_dip_courseproject_django/venv/lib/python3.8/site-packages/django/core/handlers/base.py", line 197, in _get_response
    response = wrapped_callback(request, *callback_args, **callback_kwargs)
  File "/Users/key/PycharmProjects/python_dip_courseproject_django/venv/lib/python3.8/site-packages/django/views/decorators/csrf.py", line 54, in wrapped_view
    return view_func(*args, **kwargs)
  File "/Users/key/PycharmProjects/python_dip_courseproject_django/venv/lib/python3.8/site-packages/django/views/generic/base.py", line 84, in view
    return self.dispatch(request, *args, **kwargs)
  File "/Users/key/PycharmProjects/python_dip_courseproject_django/venv/lib/python3.8/site-packages/rest_framework/views.py", line 509, in dispatch
    response = self.handle_exception(exc)
  File "/Users/key/PycharmProjects/python_dip_courseproject_django/venv/lib/python3.8/site-packages/rest_framework/views.py", line 469, in handle_exception
    self.raise_uncaught_exception(exc)
  File "/Users/key/PycharmProjects/python_dip_courseproject_django/venv/lib/python3.8/site-packages/rest_framework/views.py", line 480, in raise_uncaught_exception
    raise exc
  File "/Users/key/PycharmProjects/python_dip_courseproject_django/venv/lib/python3.8/site-packages/rest_framework/views.py", line 506, in dispatch
    response = handler(request, *args, **kwargs)
  File "/Users/key/PycharmProjects/python_dip_courseproject_django/api/views.py", line 55, in post
    resize(zoomXValue,zoomYValue,filePath)
TypeError: __init__() takes 1 positional argument but 4 were given
ERROR 2022-05-15 14:46:47,931 [Thread-1:6193360896] [django.request:241] [log:log_response] [ERROR]- Internal Server Error: /api/resize/
Traceback (most recent call last):
  File "/Users/key/PycharmProjects/python_dip_courseproject_django/venv/lib/python3.8/site-packages/django/core/handlers/exception.py", line 55, in inner
    response = get_response(request)
  File "/Users/key/PycharmProjects/python_dip_courseproject_django/venv/lib/python3.8/site-packages/django/core/handlers/base.py", line 197, in _get_response
    response = wrapped_callback(request, *callback_args, **callback_kwargs)
  File "/Users/key/PycharmProjects/python_dip_courseproject_django/venv/lib/python3.8/site-packages/django/views/decorators/csrf.py", line 54, in wrapped_view
    return view_func(*args, **kwargs)
  File "/Users/key/PycharmProjects/python_dip_courseproject_django/venv/lib/python3.8/site-packages/django/views/generic/base.py", line 84, in view
    return self.dispatch(request, *args, **kwargs)
  File "/Users/key/PycharmProjects/python_dip_courseproject_django/venv/lib/python3.8/site-packages/rest_framework/views.py", line 509, in dispatch
    response = self.handle_exception(exc)
  File "/Users/key/PycharmProjects/python_dip_courseproject_django/venv/lib/python3.8/site-packages/rest_framework/views.py", line 469, in handle_exception
    self.raise_uncaught_exception(exc)
  File "/Users/key/PycharmProjects/python_dip_courseproject_django/venv/lib/python3.8/site-packages/rest_framework/views.py", line 480, in raise_uncaught_exception
    raise exc
  File "/Users/key/PycharmProjects/python_dip_courseproject_django/venv/lib/python3.8/site-packages/rest_framework/views.py", line 506, in dispatch
    response = handler(request, *args, **kwargs)
  File "/Users/key/PycharmProjects/python_dip_courseproject_django/api/views.py", line 55, in post
    imageResize(zoomXValue,zoomYValue,filePath)
  File "/Users/key/PycharmProjects/python_dip_courseproject_django/lib/manage/imageProcess.py", line 5, in imageResize
    out = cv2.resize(filePath, (x, y))
cv2.error: OpenCV(4.5.5) :-1: error: (-5:Bad argument) in function 'resize'
> Overload resolution failed:
>  - src is not a numpy array, neither a scalar
>  - Expected Ptr<cv::UMat> for argument 'src'

ERROR 2022-05-15 14:48:10,456 [Thread-1:6192869376] [django.request:241] [log:log_response] [ERROR]- Internal Server Error: /api/resize/
Traceback (most recent call last):
  File "/Users/key/PycharmProjects/python_dip_courseproject_django/venv/lib/python3.8/site-packages/django/core/handlers/exception.py", line 55, in inner
    response = get_response(request)
  File "/Users/key/PycharmProjects/python_dip_courseproject_django/venv/lib/python3.8/site-packages/django/core/handlers/base.py", line 197, in _get_response
    response = wrapped_callback(request, *callback_args, **callback_kwargs)
  File "/Users/key/PycharmProjects/python_dip_courseproject_django/venv/lib/python3.8/site-packages/django/views/decorators/csrf.py", line 54, in wrapped_view
    return view_func(*args, **kwargs)
  File "/Users/key/PycharmProjects/python_dip_courseproject_django/venv/lib/python3.8/site-packages/django/views/generic/base.py", line 84, in view
    return self.dispatch(request, *args, **kwargs)
  File "/Users/key/PycharmProjects/python_dip_courseproject_django/venv/lib/python3.8/site-packages/rest_framework/views.py", line 509, in dispatch
    response = self.handle_exception(exc)
  File "/Users/key/PycharmProjects/python_dip_courseproject_django/venv/lib/python3.8/site-packages/rest_framework/views.py", line 469, in handle_exception
    self.raise_uncaught_exception(exc)
  File "/Users/key/PycharmProjects/python_dip_courseproject_django/venv/lib/python3.8/site-packages/rest_framework/views.py", line 480, in raise_uncaught_exception
    raise exc
  File "/Users/key/PycharmProjects/python_dip_courseproject_django/venv/lib/python3.8/site-packages/rest_framework/views.py", line 506, in dispatch
    response = handler(request, *args, **kwargs)
  File "/Users/key/PycharmProjects/python_dip_courseproject_django/api/views.py", line 55, in post
    imageResize(zoomXValue,zoomYValue,filePath)
  File "/Users/key/PycharmProjects/python_dip_courseproject_django/lib/manage/imageProcess.py", line 5, in imageResize
    out = cv2.resize(filePath, (x, y))
cv2.error: OpenCV(4.5.5) :-1: error: (-5:Bad argument) in function 'resize'
> Overload resolution failed:
>  - src is not a numpy array, neither a scalar
>  - Expected Ptr<cv::UMat> for argument 'src'

ERROR 2022-05-15 14:56:12,271 [Thread-1:6168752128] [django.request:241] [log:log_response] [ERROR]- Internal Server Error: /api/resize/
Traceback (most recent call last):
  File "/Users/key/PycharmProjects/python_dip_courseproject_django/venv/lib/python3.8/site-packages/django/core/handlers/exception.py", line 55, in inner
    response = get_response(request)
  File "/Users/key/PycharmProjects/python_dip_courseproject_django/venv/lib/python3.8/site-packages/django/core/handlers/base.py", line 197, in _get_response
    response = wrapped_callback(request, *callback_args, **callback_kwargs)
  File "/Users/key/PycharmProjects/python_dip_courseproject_django/venv/lib/python3.8/site-packages/django/views/decorators/csrf.py", line 54, in wrapped_view
    return view_func(*args, **kwargs)
  File "/Users/key/PycharmProjects/python_dip_courseproject_django/venv/lib/python3.8/site-packages/django/views/generic/base.py", line 84, in view
    return self.dispatch(request, *args, **kwargs)
  File "/Users/key/PycharmProjects/python_dip_courseproject_django/venv/lib/python3.8/site-packages/rest_framework/views.py", line 509, in dispatch
    response = self.handle_exception(exc)
  File "/Users/key/PycharmProjects/python_dip_courseproject_django/venv/lib/python3.8/site-packages/rest_framework/views.py", line 469, in handle_exception
    self.raise_uncaught_exception(exc)
  File "/Users/key/PycharmProjects/python_dip_courseproject_django/venv/lib/python3.8/site-packages/rest_framework/views.py", line 480, in raise_uncaught_exception
    raise exc
  File "/Users/key/PycharmProjects/python_dip_courseproject_django/venv/lib/python3.8/site-packages/rest_framework/views.py", line 506, in dispatch
    response = handler(request, *args, **kwargs)
  File "/Users/key/PycharmProjects/python_dip_courseproject_django/api/views.py", line 55, in post
    imageResize(zoomXValue,zoomYValue,filePath)
  File "/Users/key/PycharmProjects/python_dip_courseproject_django/lib/manage/imageProcess.py", line 7, in imageResize
    out = cv2.resize(filePath, (x, y))
cv2.error: OpenCV(4.5.5) :-1: error: (-5:Bad argument) in function 'resize'
> Overload resolution failed:
>  - src is not a numpy array, neither a scalar
>  - Expected Ptr<cv::UMat> for argument 'src'

ERROR 2022-05-15 14:59:53,433 [Thread-1:6174126080] [django.request:241] [log:log_response] [ERROR]- Internal Server Error: /api/resize/
Traceback (most recent call last):
  File "/Users/key/PycharmProjects/python_dip_courseproject_django/venv/lib/python3.8/site-packages/django/core/handlers/exception.py", line 55, in inner
    response = get_response(request)
  File "/Users/key/PycharmProjects/python_dip_courseproject_django/venv/lib/python3.8/site-packages/django/core/handlers/base.py", line 197, in _get_response
    response = wrapped_callback(request, *callback_args, **callback_kwargs)
  File "/Users/key/PycharmProjects/python_dip_courseproject_django/venv/lib/python3.8/site-packages/django/views/decorators/csrf.py", line 54, in wrapped_view
    return view_func(*args, **kwargs)
  File "/Users/key/PycharmProjects/python_dip_courseproject_django/venv/lib/python3.8/site-packages/django/views/generic/base.py", line 84, in view
    return self.dispatch(request, *args, **kwargs)
  File "/Users/key/PycharmProjects/python_dip_courseproject_django/venv/lib/python3.8/site-packages/rest_framework/views.py", line 509, in dispatch
    response = self.handle_exception(exc)
  File "/Users/key/PycharmProjects/python_dip_courseproject_django/venv/lib/python3.8/site-packages/rest_framework/views.py", line 469, in handle_exception
    self.raise_uncaught_exception(exc)
  File "/Users/key/PycharmProjects/python_dip_courseproject_django/venv/lib/python3.8/site-packages/rest_framework/views.py", line 480, in raise_uncaught_exception
    raise exc
  File "/Users/key/PycharmProjects/python_dip_courseproject_django/venv/lib/python3.8/site-packages/rest_framework/views.py", line 506, in dispatch
    response = handler(request, *args, **kwargs)
  File "/Users/key/PycharmProjects/python_dip_courseproject_django/api/views.py", line 55, in post
    imageResize(zoomXValue,zoomYValue,filePath)
  File "/Users/key/PycharmProjects/python_dip_courseproject_django/lib/manage/imageProcess.py", line 7, in imageResize
    out = cv2.resize(img, fx=x, fy=y)
cv2.error: OpenCV(4.5.5) :-1: error: (-5:Bad argument) in function 'resize'
> Overload resolution failed:
>  - resize() missing required argument 'dsize' (pos 2)
>  - resize() missing required argument 'dsize' (pos 2)

ERROR 2022-05-15 15:01:19,473 [Thread-1:6174912512] [django.request:241] [log:log_response] [ERROR]- Internal Server Error: /api/resize/
Traceback (most recent call last):
  File "/Users/key/PycharmProjects/python_dip_courseproject_django/venv/lib/python3.8/site-packages/django/core/handlers/exception.py", line 55, in inner
    response = get_response(request)
  File "/Users/key/PycharmProjects/python_dip_courseproject_django/venv/lib/python3.8/site-packages/django/core/handlers/base.py", line 197, in _get_response
    response = wrapped_callback(request, *callback_args, **callback_kwargs)
  File "/Users/key/PycharmProjects/python_dip_courseproject_django/venv/lib/python3.8/site-packages/django/views/decorators/csrf.py", line 54, in wrapped_view
    return view_func(*args, **kwargs)
  File "/Users/key/PycharmProjects/python_dip_courseproject_django/venv/lib/python3.8/site-packages/django/views/generic/base.py", line 84, in view
    return self.dispatch(request, *args, **kwargs)
  File "/Users/key/PycharmProjects/python_dip_courseproject_django/venv/lib/python3.8/site-packages/rest_framework/views.py", line 509, in dispatch
    response = self.handle_exception(exc)
  File "/Users/key/PycharmProjects/python_dip_courseproject_django/venv/lib/python3.8/site-packages/rest_framework/views.py", line 469, in handle_exception
    self.raise_uncaught_exception(exc)
  File "/Users/key/PycharmProjects/python_dip_courseproject_django/venv/lib/python3.8/site-packages/rest_framework/views.py", line 480, in raise_uncaught_exception
    raise exc
  File "/Users/key/PycharmProjects/python_dip_courseproject_django/venv/lib/python3.8/site-packages/rest_framework/views.py", line 506, in dispatch
    response = handler(request, *args, **kwargs)
  File "/Users/key/PycharmProjects/python_dip_courseproject_django/api/views.py", line 55, in post
    imageResize(zoomXValue,zoomYValue,filePath)
  File "/Users/key/PycharmProjects/python_dip_courseproject_django/lib/manage/imageProcess.py", line 7, in imageResize
    out = cv2.resize(img,None, fx=x, fy=y,interpolation=cv2.INTER_CUBIC)
cv2.error: OpenCV(4.5.5) :-1: error: (-5:Bad argument) in function 'resize'
> Overload resolution failed:
>  - Argument 'fx' can not be treated as a double
>  - Argument 'fx' can not be treated as a double

ERROR 2022-05-15 15:02:45,076 [Thread-5:6245642240] [django.request:241] [log:log_response] [ERROR]- Internal Server Error: /api/resize/
Traceback (most recent call last):
  File "/Users/key/PycharmProjects/python_dip_courseproject_django/venv/lib/python3.8/site-packages/django/core/handlers/exception.py", line 55, in inner
    response = get_response(request)
  File "/Users/key/PycharmProjects/python_dip_courseproject_django/venv/lib/python3.8/site-packages/django/core/handlers/base.py", line 197, in _get_response
    response = wrapped_callback(request, *callback_args, **callback_kwargs)
  File "/Users/key/PycharmProjects/python_dip_courseproject_django/venv/lib/python3.8/site-packages/django/views/decorators/csrf.py", line 54, in wrapped_view
    return view_func(*args, **kwargs)
  File "/Users/key/PycharmProjects/python_dip_courseproject_django/venv/lib/python3.8/site-packages/django/views/generic/base.py", line 84, in view
    return self.dispatch(request, *args, **kwargs)
  File "/Users/key/PycharmProjects/python_dip_courseproject_django/venv/lib/python3.8/site-packages/rest_framework/views.py", line 509, in dispatch
    response = self.handle_exception(exc)
  File "/Users/key/PycharmProjects/python_dip_courseproject_django/venv/lib/python3.8/site-packages/rest_framework/views.py", line 469, in handle_exception
    self.raise_uncaught_exception(exc)
  File "/Users/key/PycharmProjects/python_dip_courseproject_django/venv/lib/python3.8/site-packages/rest_framework/views.py", line 480, in raise_uncaught_exception
    raise exc
  File "/Users/key/PycharmProjects/python_dip_courseproject_django/venv/lib/python3.8/site-packages/rest_framework/views.py", line 506, in dispatch
    response = handler(request, *args, **kwargs)
  File "/Users/key/PycharmProjects/python_dip_courseproject_django/api/views.py", line 55, in post
    imageResize(zoomXValue,zoomYValue,filePath)
  File "/Users/key/PycharmProjects/python_dip_courseproject_django/lib/manage/imageProcess.py", line 7, in imageResize
    out = cv2.resize(img,None, fx=x, fy=y,interpolation=cv2.INTER_CUBIC)
cv2.error: OpenCV(4.5.5) :-1: error: (-5:Bad argument) in function 'resize'
> Overload resolution failed:
>  - Argument 'fx' can not be treated as a double
>  - Argument 'fx' can not be treated as a double

ERROR 2022-05-15 15:04:02,598 [Thread-5:6223392768] [django.request:241] [log:log_response] [ERROR]- Internal Server Error: /api/resize/
Traceback (most recent call last):
  File "/Users/key/PycharmProjects/python_dip_courseproject_django/venv/lib/python3.8/site-packages/django/core/handlers/exception.py", line 55, in inner
    response = get_response(request)
  File "/Users/key/PycharmProjects/python_dip_courseproject_django/venv/lib/python3.8/site-packages/django/core/handlers/base.py", line 197, in _get_response
    response = wrapped_callback(request, *callback_args, **callback_kwargs)
  File "/Users/key/PycharmProjects/python_dip_courseproject_django/venv/lib/python3.8/site-packages/django/views/decorators/csrf.py", line 54, in wrapped_view
    return view_func(*args, **kwargs)
  File "/Users/key/PycharmProjects/python_dip_courseproject_django/venv/lib/python3.8/site-packages/django/views/generic/base.py", line 84, in view
    return self.dispatch(request, *args, **kwargs)
  File "/Users/key/PycharmProjects/python_dip_courseproject_django/venv/lib/python3.8/site-packages/rest_framework/views.py", line 509, in dispatch
    response = self.handle_exception(exc)
  File "/Users/key/PycharmProjects/python_dip_courseproject_django/venv/lib/python3.8/site-packages/rest_framework/views.py", line 469, in handle_exception
    self.raise_uncaught_exception(exc)
  File "/Users/key/PycharmProjects/python_dip_courseproject_django/venv/lib/python3.8/site-packages/rest_framework/views.py", line 480, in raise_uncaught_exception
    raise exc
  File "/Users/key/PycharmProjects/python_dip_courseproject_django/venv/lib/python3.8/site-packages/rest_framework/views.py", line 506, in dispatch
    response = handler(request, *args, **kwargs)
  File "/Users/key/PycharmProjects/python_dip_courseproject_django/api/views.py", line 55, in post
    imageResize(zoomXValue,zoomYValue,filePath)
  File "/Users/key/PycharmProjects/python_dip_courseproject_django/lib/manage/imageProcess.py", line 7, in imageResize
    cv2.imshow('image', img)
cv2.error: Unknown C++ exception from OpenCV code
ERROR 2022-05-15 15:04:14,796 [Thread-5:6225686528] [django.request:241] [log:log_response] [ERROR]- Internal Server Error: /api/resize/
Traceback (most recent call last):
  File "/Users/key/PycharmProjects/python_dip_courseproject_django/venv/lib/python3.8/site-packages/django/core/handlers/exception.py", line 55, in inner
    response = get_response(request)
  File "/Users/key/PycharmProjects/python_dip_courseproject_django/venv/lib/python3.8/site-packages/django/core/handlers/base.py", line 197, in _get_response
    response = wrapped_callback(request, *callback_args, **callback_kwargs)
  File "/Users/key/PycharmProjects/python_dip_courseproject_django/venv/lib/python3.8/site-packages/django/views/decorators/csrf.py", line 54, in wrapped_view
    return view_func(*args, **kwargs)
  File "/Users/key/PycharmProjects/python_dip_courseproject_django/venv/lib/python3.8/site-packages/django/views/generic/base.py", line 84, in view
    return self.dispatch(request, *args, **kwargs)
  File "/Users/key/PycharmProjects/python_dip_courseproject_django/venv/lib/python3.8/site-packages/rest_framework/views.py", line 509, in dispatch
    response = self.handle_exception(exc)
  File "/Users/key/PycharmProjects/python_dip_courseproject_django/venv/lib/python3.8/site-packages/rest_framework/views.py", line 469, in handle_exception
    self.raise_uncaught_exception(exc)
  File "/Users/key/PycharmProjects/python_dip_courseproject_django/venv/lib/python3.8/site-packages/rest_framework/views.py", line 480, in raise_uncaught_exception
    raise exc
  File "/Users/key/PycharmProjects/python_dip_courseproject_django/venv/lib/python3.8/site-packages/rest_framework/views.py", line 506, in dispatch
    response = handler(request, *args, **kwargs)
  File "/Users/key/PycharmProjects/python_dip_courseproject_django/api/views.py", line 55, in post
    imageResize(zoomXValue,zoomYValue,filePath)
  File "/Users/key/PycharmProjects/python_dip_courseproject_django/lib/manage/imageProcess.py", line 7, in imageResize
    cv2.imshow('image', img)
cv2.error: Unknown C++ exception from OpenCV code
ERROR 2022-05-15 15:05:29,929 [Thread-5:6223867904] [django.request:241] [log:log_response] [ERROR]- Internal Server Error: /api/resize/
Traceback (most recent call last):
  File "/Users/key/PycharmProjects/python_dip_courseproject_django/venv/lib/python3.8/site-packages/django/core/handlers/exception.py", line 55, in inner
    response = get_response(request)
  File "/Users/key/PycharmProjects/python_dip_courseproject_django/venv/lib/python3.8/site-packages/django/core/handlers/base.py", line 197, in _get_response
    response = wrapped_callback(request, *callback_args, **callback_kwargs)
  File "/Users/key/PycharmProjects/python_dip_courseproject_django/venv/lib/python3.8/site-packages/django/views/decorators/csrf.py", line 54, in wrapped_view
    return view_func(*args, **kwargs)
  File "/Users/key/PycharmProjects/python_dip_courseproject_django/venv/lib/python3.8/site-packages/django/views/generic/base.py", line 84, in view
    return self.dispatch(request, *args, **kwargs)
  File "/Users/key/PycharmProjects/python_dip_courseproject_django/venv/lib/python3.8/site-packages/rest_framework/views.py", line 509, in dispatch
    response = self.handle_exception(exc)
  File "/Users/key/PycharmProjects/python_dip_courseproject_django/venv/lib/python3.8/site-packages/rest_framework/views.py", line 469, in handle_exception
    self.raise_uncaught_exception(exc)
  File "/Users/key/PycharmProjects/python_dip_courseproject_django/venv/lib/python3.8/site-packages/rest_framework/views.py", line 480, in raise_uncaught_exception
    raise exc
  File "/Users/key/PycharmProjects/python_dip_courseproject_django/venv/lib/python3.8/site-packages/rest_framework/views.py", line 506, in dispatch
    response = handler(request, *args, **kwargs)
  File "/Users/key/PycharmProjects/python_dip_courseproject_django/api/views.py", line 55, in post
    imageResize(zoomXValue,zoomYValue,filePath)
  File "/Users/key/PycharmProjects/python_dip_courseproject_django/lib/manage/imageProcess.py", line 7, in imageResize
    out = cv2.resize(img,None, fx=x, fy=y,interpolation=cv2.INTER_LINEAR)
cv2.error: OpenCV(4.5.5) :-1: error: (-5:Bad argument) in function 'resize'
> Overload resolution failed:
>  - Argument 'fx' can not be treated as a double
>  - Argument 'fx' can not be treated as a double

ERROR 2022-05-15 16:11:24,908 [Thread-5:6220607488] [django.request:241] [log:log_response] [ERROR]- Internal Server Error: /api/resize/
Traceback (most recent call last):
  File "/Users/key/PycharmProjects/python_dip_courseproject_django/venv/lib/python3.8/site-packages/django/core/handlers/exception.py", line 55, in inner
    response = get_response(request)
  File "/Users/key/PycharmProjects/python_dip_courseproject_django/venv/lib/python3.8/site-packages/django/core/handlers/base.py", line 197, in _get_response
    response = wrapped_callback(request, *callback_args, **callback_kwargs)
  File "/Users/key/PycharmProjects/python_dip_courseproject_django/venv/lib/python3.8/site-packages/django/views/decorators/csrf.py", line 54, in wrapped_view
    return view_func(*args, **kwargs)
  File "/Users/key/PycharmProjects/python_dip_courseproject_django/venv/lib/python3.8/site-packages/django/views/generic/base.py", line 84, in view
    return self.dispatch(request, *args, **kwargs)
  File "/Users/key/PycharmProjects/python_dip_courseproject_django/venv/lib/python3.8/site-packages/rest_framework/views.py", line 509, in dispatch
    response = self.handle_exception(exc)
  File "/Users/key/PycharmProjects/python_dip_courseproject_django/venv/lib/python3.8/site-packages/rest_framework/views.py", line 469, in handle_exception
    self.raise_uncaught_exception(exc)
  File "/Users/key/PycharmProjects/python_dip_courseproject_django/venv/lib/python3.8/site-packages/rest_framework/views.py", line 480, in raise_uncaught_exception
    raise exc
  File "/Users/key/PycharmProjects/python_dip_courseproject_django/venv/lib/python3.8/site-packages/rest_framework/views.py", line 506, in dispatch
    response = handler(request, *args, **kwargs)
  File "/Users/key/PycharmProjects/python_dip_courseproject_django/api/views.py", line 52, in post
    imageResize(zoomXValue, zoomYValue, filePath)
  File "/Users/key/PycharmProjects/python_dip_courseproject_django/lib/manage/imageProcess.py", line 10, in imageResize
    out = cv2.resize(img,None, fx=x, fy=y,interpolation=cv2.INTER_LINEAR)
cv2.error: OpenCV(4.5.5) /Users/xperience/actions-runner/_work/opencv-python/opencv-python/opencv/modules/imgproc/src/resize.cpp:4052: error: (-215:Assertion failed) !ssize.empty() in function 'resize'

ERROR 2022-05-15 16:15:48,055 [Thread-1:6208040960] [django.request:241] [log:log_response] [ERROR]- Internal Server Error: /api/resize/
Traceback (most recent call last):
  File "/Users/key/PycharmProjects/python_dip_courseproject_django/venv/lib/python3.8/site-packages/django/core/handlers/exception.py", line 55, in inner
    response = get_response(request)
  File "/Users/key/PycharmProjects/python_dip_courseproject_django/venv/lib/python3.8/site-packages/django/core/handlers/base.py", line 197, in _get_response
    response = wrapped_callback(request, *callback_args, **callback_kwargs)
  File "/Users/key/PycharmProjects/python_dip_courseproject_django/venv/lib/python3.8/site-packages/django/views/decorators/csrf.py", line 54, in wrapped_view
    return view_func(*args, **kwargs)
  File "/Users/key/PycharmProjects/python_dip_courseproject_django/venv/lib/python3.8/site-packages/django/views/generic/base.py", line 84, in view
    return self.dispatch(request, *args, **kwargs)
  File "/Users/key/PycharmProjects/python_dip_courseproject_django/venv/lib/python3.8/site-packages/rest_framework/views.py", line 509, in dispatch
    response = self.handle_exception(exc)
  File "/Users/key/PycharmProjects/python_dip_courseproject_django/venv/lib/python3.8/site-packages/rest_framework/views.py", line 469, in handle_exception
    self.raise_uncaught_exception(exc)
  File "/Users/key/PycharmProjects/python_dip_courseproject_django/venv/lib/python3.8/site-packages/rest_framework/views.py", line 480, in raise_uncaught_exception
    raise exc
  File "/Users/key/PycharmProjects/python_dip_courseproject_django/venv/lib/python3.8/site-packages/rest_framework/views.py", line 506, in dispatch
    response = handler(request, *args, **kwargs)
  File "/Users/key/PycharmProjects/python_dip_courseproject_django/api/views.py", line 52, in post
    path = re.Match(r'/media/(.*)', serializer.data['file'])
TypeError: cannot create 're.Match' instances
ERROR 2022-05-15 16:16:01,023 [Thread-5:6214955008] [django.request:241] [log:log_response] [ERROR]- Internal Server Error: /api/resize/
Traceback (most recent call last):
  File "/Users/key/PycharmProjects/python_dip_courseproject_django/venv/lib/python3.8/site-packages/django/core/handlers/exception.py", line 55, in inner
    response = get_response(request)
  File "/Users/key/PycharmProjects/python_dip_courseproject_django/venv/lib/python3.8/site-packages/django/core/handlers/base.py", line 197, in _get_response
    response = wrapped_callback(request, *callback_args, **callback_kwargs)
  File "/Users/key/PycharmProjects/python_dip_courseproject_django/venv/lib/python3.8/site-packages/django/views/decorators/csrf.py", line 54, in wrapped_view
    return view_func(*args, **kwargs)
  File "/Users/key/PycharmProjects/python_dip_courseproject_django/venv/lib/python3.8/site-packages/django/views/generic/base.py", line 84, in view
    return self.dispatch(request, *args, **kwargs)
  File "/Users/key/PycharmProjects/python_dip_courseproject_django/venv/lib/python3.8/site-packages/rest_framework/views.py", line 509, in dispatch
    response = self.handle_exception(exc)
  File "/Users/key/PycharmProjects/python_dip_courseproject_django/venv/lib/python3.8/site-packages/rest_framework/views.py", line 469, in handle_exception
    self.raise_uncaught_exception(exc)
  File "/Users/key/PycharmProjects/python_dip_courseproject_django/venv/lib/python3.8/site-packages/rest_framework/views.py", line 480, in raise_uncaught_exception
    raise exc
  File "/Users/key/PycharmProjects/python_dip_courseproject_django/venv/lib/python3.8/site-packages/rest_framework/views.py", line 506, in dispatch
    response = handler(request, *args, **kwargs)
  File "/Users/key/PycharmProjects/python_dip_courseproject_django/api/views.py", line 52, in post
    path = re.Match(r'/media/(.*)', serializer.data['file'])
TypeError: cannot create 're.Match' instances
ERROR 2022-05-15 16:16:14,293 [Thread-5:6210105344] [django.request:241] [log:log_response] [ERROR]- Internal Server Error: /api/resize/
Traceback (most recent call last):
  File "/Users/key/PycharmProjects/python_dip_courseproject_django/venv/lib/python3.8/site-packages/django/core/handlers/exception.py", line 55, in inner
    response = get_response(request)
  File "/Users/key/PycharmProjects/python_dip_courseproject_django/venv/lib/python3.8/site-packages/django/core/handlers/base.py", line 197, in _get_response
    response = wrapped_callback(request, *callback_args, **callback_kwargs)
  File "/Users/key/PycharmProjects/python_dip_courseproject_django/venv/lib/python3.8/site-packages/django/views/decorators/csrf.py", line 54, in wrapped_view
    return view_func(*args, **kwargs)
  File "/Users/key/PycharmProjects/python_dip_courseproject_django/venv/lib/python3.8/site-packages/django/views/generic/base.py", line 84, in view
    return self.dispatch(request, *args, **kwargs)
  File "/Users/key/PycharmProjects/python_dip_courseproject_django/venv/lib/python3.8/site-packages/rest_framework/views.py", line 509, in dispatch
    response = self.handle_exception(exc)
  File "/Users/key/PycharmProjects/python_dip_courseproject_django/venv/lib/python3.8/site-packages/rest_framework/views.py", line 469, in handle_exception
    self.raise_uncaught_exception(exc)
  File "/Users/key/PycharmProjects/python_dip_courseproject_django/venv/lib/python3.8/site-packages/rest_framework/views.py", line 480, in raise_uncaught_exception
    raise exc
  File "/Users/key/PycharmProjects/python_dip_courseproject_django/venv/lib/python3.8/site-packages/rest_framework/views.py", line 506, in dispatch
    response = handler(request, *args, **kwargs)
  File "/Users/key/PycharmProjects/python_dip_courseproject_django/api/views.py", line 52, in post
    path = re.Match(r'/media/(.*)', serializer.data['file'])
TypeError: cannot create 're.Match' instances
ERROR 2022-05-15 16:16:55,008 [Thread-5:6248427520] [django.request:241] [log:log_response] [ERROR]- Internal Server Error: /api/resize/
Traceback (most recent call last):
  File "/Users/key/PycharmProjects/python_dip_courseproject_django/venv/lib/python3.8/site-packages/django/core/handlers/exception.py", line 55, in inner
    response = get_response(request)
  File "/Users/key/PycharmProjects/python_dip_courseproject_django/venv/lib/python3.8/site-packages/django/core/handlers/base.py", line 197, in _get_response
    response = wrapped_callback(request, *callback_args, **callback_kwargs)
  File "/Users/key/PycharmProjects/python_dip_courseproject_django/venv/lib/python3.8/site-packages/django/views/decorators/csrf.py", line 54, in wrapped_view
    return view_func(*args, **kwargs)
  File "/Users/key/PycharmProjects/python_dip_courseproject_django/venv/lib/python3.8/site-packages/django/views/generic/base.py", line 84, in view
    return self.dispatch(request, *args, **kwargs)
  File "/Users/key/PycharmProjects/python_dip_courseproject_django/venv/lib/python3.8/site-packages/rest_framework/views.py", line 509, in dispatch
    response = self.handle_exception(exc)
  File "/Users/key/PycharmProjects/python_dip_courseproject_django/venv/lib/python3.8/site-packages/rest_framework/views.py", line 469, in handle_exception
    self.raise_uncaught_exception(exc)
  File "/Users/key/PycharmProjects/python_dip_courseproject_django/venv/lib/python3.8/site-packages/rest_framework/views.py", line 480, in raise_uncaught_exception
    raise exc
  File "/Users/key/PycharmProjects/python_dip_courseproject_django/venv/lib/python3.8/site-packages/rest_framework/views.py", line 506, in dispatch
    response = handler(request, *args, **kwargs)
  File "/Users/key/PycharmProjects/python_dip_courseproject_django/api/views.py", line 53, in post
    print(path.group(1))
AttributeError: 'NoneType' object has no attribute 'group'
ERROR 2022-05-15 16:17:10,825 [Thread-5:6187642880] [django.request:241] [log:log_response] [ERROR]- Internal Server Error: /api/resize/
Traceback (most recent call last):
  File "/Users/key/PycharmProjects/python_dip_courseproject_django/venv/lib/python3.8/site-packages/django/core/handlers/exception.py", line 55, in inner
    response = get_response(request)
  File "/Users/key/PycharmProjects/python_dip_courseproject_django/venv/lib/python3.8/site-packages/django/core/handlers/base.py", line 197, in _get_response
    response = wrapped_callback(request, *callback_args, **callback_kwargs)
  File "/Users/key/PycharmProjects/python_dip_courseproject_django/venv/lib/python3.8/site-packages/django/views/decorators/csrf.py", line 54, in wrapped_view
    return view_func(*args, **kwargs)
  File "/Users/key/PycharmProjects/python_dip_courseproject_django/venv/lib/python3.8/site-packages/django/views/generic/base.py", line 84, in view
    return self.dispatch(request, *args, **kwargs)
  File "/Users/key/PycharmProjects/python_dip_courseproject_django/venv/lib/python3.8/site-packages/rest_framework/views.py", line 509, in dispatch
    response = self.handle_exception(exc)
  File "/Users/key/PycharmProjects/python_dip_courseproject_django/venv/lib/python3.8/site-packages/rest_framework/views.py", line 469, in handle_exception
    self.raise_uncaught_exception(exc)
  File "/Users/key/PycharmProjects/python_dip_courseproject_django/venv/lib/python3.8/site-packages/rest_framework/views.py", line 480, in raise_uncaught_exception
    raise exc
  File "/Users/key/PycharmProjects/python_dip_courseproject_django/venv/lib/python3.8/site-packages/rest_framework/views.py", line 506, in dispatch
    response = handler(request, *args, **kwargs)
  File "/Users/key/PycharmProjects/python_dip_courseproject_django/api/views.py", line 53, in post
    print(path.group(1))
AttributeError: 'NoneType' object has no attribute 'group'
ERROR 2022-05-15 16:20:58,714 [Thread-1:6165491712] [django.request:241] [log:log_response] [ERROR]- Internal Server Error: /api/resize/
Traceback (most recent call last):
  File "/Users/key/PycharmProjects/python_dip_courseproject_django/venv/lib/python3.8/site-packages/django/core/handlers/exception.py", line 55, in inner
    response = get_response(request)
  File "/Users/key/PycharmProjects/python_dip_courseproject_django/venv/lib/python3.8/site-packages/django/core/handlers/base.py", line 197, in _get_response
    response = wrapped_callback(request, *callback_args, **callback_kwargs)
  File "/Users/key/PycharmProjects/python_dip_courseproject_django/venv/lib/python3.8/site-packages/django/views/decorators/csrf.py", line 54, in wrapped_view
    return view_func(*args, **kwargs)
  File "/Users/key/PycharmProjects/python_dip_courseproject_django/venv/lib/python3.8/site-packages/django/views/generic/base.py", line 84, in view
    return self.dispatch(request, *args, **kwargs)
  File "/Users/key/PycharmProjects/python_dip_courseproject_django/venv/lib/python3.8/site-packages/rest_framework/views.py", line 509, in dispatch
    response = self.handle_exception(exc)
  File "/Users/key/PycharmProjects/python_dip_courseproject_django/venv/lib/python3.8/site-packages/rest_framework/views.py", line 469, in handle_exception
    self.raise_uncaught_exception(exc)
  File "/Users/key/PycharmProjects/python_dip_courseproject_django/venv/lib/python3.8/site-packages/rest_framework/views.py", line 480, in raise_uncaught_exception
    raise exc
  File "/Users/key/PycharmProjects/python_dip_courseproject_django/venv/lib/python3.8/site-packages/rest_framework/views.py", line 506, in dispatch
    response = handler(request, *args, **kwargs)
  File "/Users/key/PycharmProjects/python_dip_courseproject_django/api/views.py", line 54, in post
    imageResize(zoomXValue, zoomYValue, path.group())
  File "/Users/key/PycharmProjects/python_dip_courseproject_django/lib/manage/imageProcess.py", line 10, in imageResize
    out = cv2.resize(img,None, fx=x, fy=y,interpolation=cv2.INTER_LINEAR)
cv2.error: OpenCV(4.5.5) /Users/xperience/actions-runner/_work/opencv-python/opencv-python/opencv/modules/imgproc/src/resize.cpp:4052: error: (-215:Assertion failed) !ssize.empty() in function 'resize'

ERROR 2022-05-15 16:22:21,152 [Thread-1:6164295680] [django.request:241] [log:log_response] [ERROR]- Internal Server Error: /api/resize/
Traceback (most recent call last):
  File "/Users/key/PycharmProjects/python_dip_courseproject_django/venv/lib/python3.8/site-packages/django/core/handlers/exception.py", line 55, in inner
    response = get_response(request)
  File "/Users/key/PycharmProjects/python_dip_courseproject_django/venv/lib/python3.8/site-packages/django/core/handlers/base.py", line 197, in _get_response
    response = wrapped_callback(request, *callback_args, **callback_kwargs)
  File "/Users/key/PycharmProjects/python_dip_courseproject_django/venv/lib/python3.8/site-packages/django/views/decorators/csrf.py", line 54, in wrapped_view
    return view_func(*args, **kwargs)
  File "/Users/key/PycharmProjects/python_dip_courseproject_django/venv/lib/python3.8/site-packages/django/views/generic/base.py", line 84, in view
    return self.dispatch(request, *args, **kwargs)
  File "/Users/key/PycharmProjects/python_dip_courseproject_django/venv/lib/python3.8/site-packages/rest_framework/views.py", line 509, in dispatch
    response = self.handle_exception(exc)
  File "/Users/key/PycharmProjects/python_dip_courseproject_django/venv/lib/python3.8/site-packages/rest_framework/views.py", line 469, in handle_exception
    self.raise_uncaught_exception(exc)
  File "/Users/key/PycharmProjects/python_dip_courseproject_django/venv/lib/python3.8/site-packages/rest_framework/views.py", line 480, in raise_uncaught_exception
    raise exc
  File "/Users/key/PycharmProjects/python_dip_courseproject_django/venv/lib/python3.8/site-packages/rest_framework/views.py", line 506, in dispatch
    response = handler(request, *args, **kwargs)
  File "/Users/key/PycharmProjects/python_dip_courseproject_django/api/views.py", line 55, in post
    print(serializer)
  File "/Users/key/PycharmProjects/python_dip_courseproject_django/venv/lib/python3.8/site-packages/rest_framework/serializers.py", line 530, in __repr__
    return representation.serializer_repr(self, indent=1)
  File "/Users/key/PycharmProjects/python_dip_courseproject_django/venv/lib/python3.8/site-packages/rest_framework/utils/representation.py", line 71, in serializer_repr
    ret = field_repr(serializer, force_many) + ':'
  File "/Users/key/PycharmProjects/python_dip_courseproject_django/venv/lib/python3.8/site-packages/rest_framework/utils/representation.py", line 54, in field_repr
    arg_string = ', '.join([smart_repr(val) for val in field._args])
  File "/Users/key/PycharmProjects/python_dip_courseproject_django/venv/lib/python3.8/site-packages/rest_framework/utils/representation.py", line 54, in <listcomp>
    arg_string = ', '.join([smart_repr(val) for val in field._args])
  File "/Users/key/PycharmProjects/python_dip_courseproject_django/venv/lib/python3.8/site-packages/rest_framework/utils/representation.py", line 33, in smart_repr
    value = repr(value)
  File "/Users/key/PycharmProjects/python_dip_courseproject_django/venv/lib/python3.8/site-packages/django/db/models/base.py", line 580, in __repr__
    return "<%s: %s>" % (self.__class__.__name__, self)
TypeError: __str__ returned non-string (type ImageFieldFile)
ERROR 2022-05-15 16:22:38,879 [Thread-1:6165426176] [django.request:241] [log:log_response] [ERROR]- Internal Server Error: /api/resize/
Traceback (most recent call last):
  File "/Users/key/PycharmProjects/python_dip_courseproject_django/venv/lib/python3.8/site-packages/django/core/handlers/exception.py", line 55, in inner
    response = get_response(request)
  File "/Users/key/PycharmProjects/python_dip_courseproject_django/venv/lib/python3.8/site-packages/django/core/handlers/base.py", line 197, in _get_response
    response = wrapped_callback(request, *callback_args, **callback_kwargs)
  File "/Users/key/PycharmProjects/python_dip_courseproject_django/venv/lib/python3.8/site-packages/django/views/decorators/csrf.py", line 54, in wrapped_view
    return view_func(*args, **kwargs)
  File "/Users/key/PycharmProjects/python_dip_courseproject_django/venv/lib/python3.8/site-packages/django/views/generic/base.py", line 84, in view
    return self.dispatch(request, *args, **kwargs)
  File "/Users/key/PycharmProjects/python_dip_courseproject_django/venv/lib/python3.8/site-packages/rest_framework/views.py", line 509, in dispatch
    response = self.handle_exception(exc)
  File "/Users/key/PycharmProjects/python_dip_courseproject_django/venv/lib/python3.8/site-packages/rest_framework/views.py", line 469, in handle_exception
    self.raise_uncaught_exception(exc)
  File "/Users/key/PycharmProjects/python_dip_courseproject_django/venv/lib/python3.8/site-packages/rest_framework/views.py", line 480, in raise_uncaught_exception
    raise exc
  File "/Users/key/PycharmProjects/python_dip_courseproject_django/venv/lib/python3.8/site-packages/rest_framework/views.py", line 506, in dispatch
    response = handler(request, *args, **kwargs)
  File "/Users/key/PycharmProjects/python_dip_courseproject_django/api/views.py", line 55, in post
    print(serializer)
  File "/Users/key/PycharmProjects/python_dip_courseproject_django/venv/lib/python3.8/site-packages/rest_framework/serializers.py", line 530, in __repr__
    return representation.serializer_repr(self, indent=1)
  File "/Users/key/PycharmProjects/python_dip_courseproject_django/venv/lib/python3.8/site-packages/rest_framework/utils/representation.py", line 71, in serializer_repr
    ret = field_repr(serializer, force_many) + ':'
  File "/Users/key/PycharmProjects/python_dip_courseproject_django/venv/lib/python3.8/site-packages/rest_framework/utils/representation.py", line 54, in field_repr
    arg_string = ', '.join([smart_repr(val) for val in field._args])
  File "/Users/key/PycharmProjects/python_dip_courseproject_django/venv/lib/python3.8/site-packages/rest_framework/utils/representation.py", line 54, in <listcomp>
    arg_string = ', '.join([smart_repr(val) for val in field._args])
  File "/Users/key/PycharmProjects/python_dip_courseproject_django/venv/lib/python3.8/site-packages/rest_framework/utils/representation.py", line 33, in smart_repr
    value = repr(value)
  File "/Users/key/PycharmProjects/python_dip_courseproject_django/venv/lib/python3.8/site-packages/django/db/models/base.py", line 580, in __repr__
    return "<%s: %s>" % (self.__class__.__name__, self)
TypeError: __str__ returned non-string (type ImageFieldFile)
ERROR 2022-05-15 16:23:28,419 [Thread-5:6217248768] [django.request:241] [log:log_response] [ERROR]- Internal Server Error: /api/resize/
Traceback (most recent call last):
  File "/Users/key/PycharmProjects/python_dip_courseproject_django/venv/lib/python3.8/site-packages/django/core/handlers/exception.py", line 55, in inner
    response = get_response(request)
  File "/Users/key/PycharmProjects/python_dip_courseproject_django/venv/lib/python3.8/site-packages/django/core/handlers/base.py", line 197, in _get_response
    response = wrapped_callback(request, *callback_args, **callback_kwargs)
  File "/Users/key/PycharmProjects/python_dip_courseproject_django/venv/lib/python3.8/site-packages/django/views/decorators/csrf.py", line 54, in wrapped_view
    return view_func(*args, **kwargs)
  File "/Users/key/PycharmProjects/python_dip_courseproject_django/venv/lib/python3.8/site-packages/django/views/generic/base.py", line 84, in view
    return self.dispatch(request, *args, **kwargs)
  File "/Users/key/PycharmProjects/python_dip_courseproject_django/venv/lib/python3.8/site-packages/rest_framework/views.py", line 509, in dispatch
    response = self.handle_exception(exc)
  File "/Users/key/PycharmProjects/python_dip_courseproject_django/venv/lib/python3.8/site-packages/rest_framework/views.py", line 469, in handle_exception
    self.raise_uncaught_exception(exc)
  File "/Users/key/PycharmProjects/python_dip_courseproject_django/venv/lib/python3.8/site-packages/rest_framework/views.py", line 480, in raise_uncaught_exception
    raise exc
  File "/Users/key/PycharmProjects/python_dip_courseproject_django/venv/lib/python3.8/site-packages/rest_framework/views.py", line 506, in dispatch
    response = handler(request, *args, **kwargs)
  File "/Users/key/PycharmProjects/python_dip_courseproject_django/api/views.py", line 55, in post
    print(serializer)
  File "/Users/key/PycharmProjects/python_dip_courseproject_django/venv/lib/python3.8/site-packages/rest_framework/serializers.py", line 530, in __repr__
    return representation.serializer_repr(self, indent=1)
  File "/Users/key/PycharmProjects/python_dip_courseproject_django/venv/lib/python3.8/site-packages/rest_framework/utils/representation.py", line 71, in serializer_repr
    ret = field_repr(serializer, force_many) + ':'
  File "/Users/key/PycharmProjects/python_dip_courseproject_django/venv/lib/python3.8/site-packages/rest_framework/utils/representation.py", line 54, in field_repr
    arg_string = ', '.join([smart_repr(val) for val in field._args])
  File "/Users/key/PycharmProjects/python_dip_courseproject_django/venv/lib/python3.8/site-packages/rest_framework/utils/representation.py", line 54, in <listcomp>
    arg_string = ', '.join([smart_repr(val) for val in field._args])
  File "/Users/key/PycharmProjects/python_dip_courseproject_django/venv/lib/python3.8/site-packages/rest_framework/utils/representation.py", line 33, in smart_repr
    value = repr(value)
  File "/Users/key/PycharmProjects/python_dip_courseproject_django/venv/lib/python3.8/site-packages/django/db/models/base.py", line 580, in __repr__
    return "<%s: %s>" % (self.__class__.__name__, self)
TypeError: __str__ returned non-string (type ImageFieldFile)
ERROR 2022-05-15 16:24:13,477 [Thread-1:6129627136] [django.request:241] [log:log_response] [ERROR]- Internal Server Error: /api/resize/
Traceback (most recent call last):
  File "/Users/key/PycharmProjects/python_dip_courseproject_django/venv/lib/python3.8/site-packages/django/core/handlers/exception.py", line 55, in inner
    response = get_response(request)
  File "/Users/key/PycharmProjects/python_dip_courseproject_django/venv/lib/python3.8/site-packages/django/core/handlers/base.py", line 197, in _get_response
    response = wrapped_callback(request, *callback_args, **callback_kwargs)
  File "/Users/key/PycharmProjects/python_dip_courseproject_django/venv/lib/python3.8/site-packages/django/views/decorators/csrf.py", line 54, in wrapped_view
    return view_func(*args, **kwargs)
  File "/Users/key/PycharmProjects/python_dip_courseproject_django/venv/lib/python3.8/site-packages/django/views/generic/base.py", line 84, in view
    return self.dispatch(request, *args, **kwargs)
  File "/Users/key/PycharmProjects/python_dip_courseproject_django/venv/lib/python3.8/site-packages/rest_framework/views.py", line 509, in dispatch
    response = self.handle_exception(exc)
  File "/Users/key/PycharmProjects/python_dip_courseproject_django/venv/lib/python3.8/site-packages/rest_framework/views.py", line 469, in handle_exception
    self.raise_uncaught_exception(exc)
  File "/Users/key/PycharmProjects/python_dip_courseproject_django/venv/lib/python3.8/site-packages/rest_framework/views.py", line 480, in raise_uncaught_exception
    raise exc
  File "/Users/key/PycharmProjects/python_dip_courseproject_django/venv/lib/python3.8/site-packages/rest_framework/views.py", line 506, in dispatch
    response = handler(request, *args, **kwargs)
  File "/Users/key/PycharmProjects/python_dip_courseproject_django/api/views.py", line 55, in post
    print(serializer)
  File "/Users/key/PycharmProjects/python_dip_courseproject_django/venv/lib/python3.8/site-packages/rest_framework/serializers.py", line 530, in __repr__
    return representation.serializer_repr(self, indent=1)
  File "/Users/key/PycharmProjects/python_dip_courseproject_django/venv/lib/python3.8/site-packages/rest_framework/utils/representation.py", line 71, in serializer_repr
    ret = field_repr(serializer, force_many) + ':'
  File "/Users/key/PycharmProjects/python_dip_courseproject_django/venv/lib/python3.8/site-packages/rest_framework/utils/representation.py", line 54, in field_repr
    arg_string = ', '.join([smart_repr(val) for val in field._args])
  File "/Users/key/PycharmProjects/python_dip_courseproject_django/venv/lib/python3.8/site-packages/rest_framework/utils/representation.py", line 54, in <listcomp>
    arg_string = ', '.join([smart_repr(val) for val in field._args])
  File "/Users/key/PycharmProjects/python_dip_courseproject_django/venv/lib/python3.8/site-packages/rest_framework/utils/representation.py", line 33, in smart_repr
    value = repr(value)
  File "/Users/key/PycharmProjects/python_dip_courseproject_django/venv/lib/python3.8/site-packages/django/db/models/base.py", line 580, in __repr__
    return "<%s: %s>" % (self.__class__.__name__, self)
TypeError: __str__ returned non-string (type ImageFieldFile)
WARNING 2022-05-15 16:58:03,466 [Thread-3:6162706432] [django.request:241] [log:log_response] [WARNING]- Bad Request: /api/ImageSet/
WARNING 2022-05-15 16:58:22,702 [Thread-3:6162706432] [django.request:241] [log:log_response] [WARNING]- Bad Request: /api/ImageSet/
ERROR 2022-05-15 16:58:51,057 [Thread-5:6162706432] [django.request:241] [log:log_response] [ERROR]- Internal Server Error: /api/resize/
Traceback (most recent call last):
  File "/Users/key/PycharmProjects/python_dip_courseproject_django/venv/lib/python3.8/site-packages/django/core/handlers/exception.py", line 55, in inner
    response = get_response(request)
  File "/Users/key/PycharmProjects/python_dip_courseproject_django/venv/lib/python3.8/site-packages/django/core/handlers/base.py", line 197, in _get_response
    response = wrapped_callback(request, *callback_args, **callback_kwargs)
  File "/Users/key/PycharmProjects/python_dip_courseproject_django/venv/lib/python3.8/site-packages/django/views/decorators/csrf.py", line 54, in wrapped_view
    return view_func(*args, **kwargs)
  File "/Users/key/PycharmProjects/python_dip_courseproject_django/venv/lib/python3.8/site-packages/django/views/generic/base.py", line 84, in view
    return self.dispatch(request, *args, **kwargs)
  File "/Users/key/PycharmProjects/python_dip_courseproject_django/venv/lib/python3.8/site-packages/rest_framework/views.py", line 509, in dispatch
    response = self.handle_exception(exc)
  File "/Users/key/PycharmProjects/python_dip_courseproject_django/venv/lib/python3.8/site-packages/rest_framework/views.py", line 469, in handle_exception
    self.raise_uncaught_exception(exc)
  File "/Users/key/PycharmProjects/python_dip_courseproject_django/venv/lib/python3.8/site-packages/rest_framework/views.py", line 480, in raise_uncaught_exception
    raise exc
  File "/Users/key/PycharmProjects/python_dip_courseproject_django/venv/lib/python3.8/site-packages/rest_framework/views.py", line 506, in dispatch
    response = handler(request, *args, **kwargs)
  File "/Users/key/PycharmProjects/python_dip_courseproject_django/api/views.py", line 52, in post
    images = Image.objects.get(id=request.data.get('id'))
  File "/Users/key/PycharmProjects/python_dip_courseproject_django/venv/lib/python3.8/site-packages/django/db/models/manager.py", line 85, in manager_method
    return getattr(self.get_queryset(), name)(*args, **kwargs)
  File "/Users/key/PycharmProjects/python_dip_courseproject_django/venv/lib/python3.8/site-packages/django/db/models/query.py", line 496, in get
    raise self.model.DoesNotExist(
api.models.Image.DoesNotExist: Image matching query does not exist.
ERROR 2022-05-15 16:58:58,510 [Thread-5:6162706432] [django.request:241] [log:log_response] [ERROR]- Internal Server Error: /api/resize/
Traceback (most recent call last):
  File "/Users/key/PycharmProjects/python_dip_courseproject_django/venv/lib/python3.8/site-packages/django/core/handlers/exception.py", line 55, in inner
    response = get_response(request)
  File "/Users/key/PycharmProjects/python_dip_courseproject_django/venv/lib/python3.8/site-packages/django/core/handlers/base.py", line 197, in _get_response
    response = wrapped_callback(request, *callback_args, **callback_kwargs)
  File "/Users/key/PycharmProjects/python_dip_courseproject_django/venv/lib/python3.8/site-packages/django/views/decorators/csrf.py", line 54, in wrapped_view
    return view_func(*args, **kwargs)
  File "/Users/key/PycharmProjects/python_dip_courseproject_django/venv/lib/python3.8/site-packages/django/views/generic/base.py", line 84, in view
    return self.dispatch(request, *args, **kwargs)
  File "/Users/key/PycharmProjects/python_dip_courseproject_django/venv/lib/python3.8/site-packages/rest_framework/views.py", line 509, in dispatch
    response = self.handle_exception(exc)
  File "/Users/key/PycharmProjects/python_dip_courseproject_django/venv/lib/python3.8/site-packages/rest_framework/views.py", line 469, in handle_exception
    self.raise_uncaught_exception(exc)
  File "/Users/key/PycharmProjects/python_dip_courseproject_django/venv/lib/python3.8/site-packages/rest_framework/views.py", line 480, in raise_uncaught_exception
    raise exc
  File "/Users/key/PycharmProjects/python_dip_courseproject_django/venv/lib/python3.8/site-packages/rest_framework/views.py", line 506, in dispatch
    response = handler(request, *args, **kwargs)
  File "/Users/key/PycharmProjects/python_dip_courseproject_django/api/views.py", line 52, in post
    images = Image.objects.get(id=request.data.get('id'))
  File "/Users/key/PycharmProjects/python_dip_courseproject_django/venv/lib/python3.8/site-packages/django/db/models/manager.py", line 85, in manager_method
    return getattr(self.get_queryset(), name)(*args, **kwargs)
  File "/Users/key/PycharmProjects/python_dip_courseproject_django/venv/lib/python3.8/site-packages/django/db/models/query.py", line 496, in get
    raise self.model.DoesNotExist(
api.models.Image.DoesNotExist: Image matching query does not exist.
ERROR 2022-05-15 16:59:46,808 [Thread-5:6162706432] [django.request:241] [log:log_response] [ERROR]- Internal Server Error: /api/resize/
Traceback (most recent call last):
  File "/Users/key/PycharmProjects/python_dip_courseproject_django/venv/lib/python3.8/site-packages/django/core/handlers/exception.py", line 55, in inner
    response = get_response(request)
  File "/Users/key/PycharmProjects/python_dip_courseproject_django/venv/lib/python3.8/site-packages/django/core/handlers/base.py", line 197, in _get_response
    response = wrapped_callback(request, *callback_args, **callback_kwargs)
  File "/Users/key/PycharmProjects/python_dip_courseproject_django/venv/lib/python3.8/site-packages/django/views/decorators/csrf.py", line 54, in wrapped_view
    return view_func(*args, **kwargs)
  File "/Users/key/PycharmProjects/python_dip_courseproject_django/venv/lib/python3.8/site-packages/django/views/generic/base.py", line 84, in view
    return self.dispatch(request, *args, **kwargs)
  File "/Users/key/PycharmProjects/python_dip_courseproject_django/venv/lib/python3.8/site-packages/rest_framework/views.py", line 509, in dispatch
    response = self.handle_exception(exc)
  File "/Users/key/PycharmProjects/python_dip_courseproject_django/venv/lib/python3.8/site-packages/rest_framework/views.py", line 469, in handle_exception
    self.raise_uncaught_exception(exc)
  File "/Users/key/PycharmProjects/python_dip_courseproject_django/venv/lib/python3.8/site-packages/rest_framework/views.py", line 480, in raise_uncaught_exception
    raise exc
  File "/Users/key/PycharmProjects/python_dip_courseproject_django/venv/lib/python3.8/site-packages/rest_framework/views.py", line 506, in dispatch
    response = handler(request, *args, **kwargs)
  File "/Users/key/PycharmProjects/python_dip_courseproject_django/api/views.py", line 52, in post
    images = Image.objects.get(id=request.data.get('id'))
  File "/Users/key/PycharmProjects/python_dip_courseproject_django/venv/lib/python3.8/site-packages/django/db/models/manager.py", line 85, in manager_method
    return getattr(self.get_queryset(), name)(*args, **kwargs)
  File "/Users/key/PycharmProjects/python_dip_courseproject_django/venv/lib/python3.8/site-packages/django/db/models/query.py", line 496, in get
    raise self.model.DoesNotExist(
api.models.Image.DoesNotExist: Image matching query does not exist.
ERROR 2022-05-15 17:00:56,634 [Thread-5:6162706432] [django.request:241] [log:log_response] [ERROR]- Internal Server Error: /api/resize/
Traceback (most recent call last):
  File "/Users/key/PycharmProjects/python_dip_courseproject_django/venv/lib/python3.8/site-packages/django/core/handlers/exception.py", line 55, in inner
    response = get_response(request)
  File "/Users/key/PycharmProjects/python_dip_courseproject_django/venv/lib/python3.8/site-packages/django/core/handlers/base.py", line 197, in _get_response
    response = wrapped_callback(request, *callback_args, **callback_kwargs)
  File "/Users/key/PycharmProjects/python_dip_courseproject_django/venv/lib/python3.8/site-packages/django/views/decorators/csrf.py", line 54, in wrapped_view
    return view_func(*args, **kwargs)
  File "/Users/key/PycharmProjects/python_dip_courseproject_django/venv/lib/python3.8/site-packages/django/views/generic/base.py", line 84, in view
    return self.dispatch(request, *args, **kwargs)
  File "/Users/key/PycharmProjects/python_dip_courseproject_django/venv/lib/python3.8/site-packages/rest_framework/views.py", line 509, in dispatch
    response = self.handle_exception(exc)
  File "/Users/key/PycharmProjects/python_dip_courseproject_django/venv/lib/python3.8/site-packages/rest_framework/views.py", line 469, in handle_exception
    self.raise_uncaught_exception(exc)
  File "/Users/key/PycharmProjects/python_dip_courseproject_django/venv/lib/python3.8/site-packages/rest_framework/views.py", line 480, in raise_uncaught_exception
    raise exc
  File "/Users/key/PycharmProjects/python_dip_courseproject_django/venv/lib/python3.8/site-packages/rest_framework/views.py", line 506, in dispatch
    response = handler(request, *args, **kwargs)
  File "/Users/key/PycharmProjects/python_dip_courseproject_django/api/views.py", line 52, in post
    images = Image.objects.get(id=request.data.get('id'))
  File "/Users/key/PycharmProjects/python_dip_courseproject_django/venv/lib/python3.8/site-packages/django/db/models/manager.py", line 85, in manager_method
    return getattr(self.get_queryset(), name)(*args, **kwargs)
  File "/Users/key/PycharmProjects/python_dip_courseproject_django/venv/lib/python3.8/site-packages/django/db/models/query.py", line 496, in get
    raise self.model.DoesNotExist(
api.models.Image.DoesNotExist: Image matching query does not exist.
ERROR 2022-05-15 17:09:24,379 [Thread-5:6162706432] [django.request:241] [log:log_response] [ERROR]- Internal Server Error: /api/resize/
Traceback (most recent call last):
  File "/Users/key/PycharmProjects/python_dip_courseproject_django/venv/lib/python3.8/site-packages/django/core/handlers/exception.py", line 55, in inner
    response = get_response(request)
  File "/Users/key/PycharmProjects/python_dip_courseproject_django/venv/lib/python3.8/site-packages/django/core/handlers/base.py", line 197, in _get_response
    response = wrapped_callback(request, *callback_args, **callback_kwargs)
  File "/Users/key/PycharmProjects/python_dip_courseproject_django/venv/lib/python3.8/site-packages/django/views/decorators/csrf.py", line 54, in wrapped_view
    return view_func(*args, **kwargs)
  File "/Users/key/PycharmProjects/python_dip_courseproject_django/venv/lib/python3.8/site-packages/django/views/generic/base.py", line 84, in view
    return self.dispatch(request, *args, **kwargs)
  File "/Users/key/PycharmProjects/python_dip_courseproject_django/venv/lib/python3.8/site-packages/rest_framework/views.py", line 509, in dispatch
    response = self.handle_exception(exc)
  File "/Users/key/PycharmProjects/python_dip_courseproject_django/venv/lib/python3.8/site-packages/rest_framework/views.py", line 469, in handle_exception
    self.raise_uncaught_exception(exc)
  File "/Users/key/PycharmProjects/python_dip_courseproject_django/venv/lib/python3.8/site-packages/rest_framework/views.py", line 480, in raise_uncaught_exception
    raise exc
  File "/Users/key/PycharmProjects/python_dip_courseproject_django/venv/lib/python3.8/site-packages/rest_framework/views.py", line 506, in dispatch
    response = handler(request, *args, **kwargs)
  File "/Users/key/PycharmProjects/python_dip_courseproject_django/api/views.py", line 57, in post
    imageResize(zoomXValue, zoomYValue, path)
  File "/Users/key/PycharmProjects/python_dip_courseproject_django/lib/manage/imageProcess.py", line 10, in imageResize
    out = cv2.resize(img,None, fx=x, fy=y,interpolation=cv2.INTER_LINEAR)
cv2.error: OpenCV(4.5.5) /Users/xperience/actions-runner/_work/opencv-python/opencv-python/opencv/modules/imgproc/src/resize.cpp:4052: error: (-215:Assertion failed) !ssize.empty() in function 'resize'

ERROR 2022-05-15 17:25:22,154 [Thread-1:6130003968] [django.request:241] [log:log_response] [ERROR]- Internal Server Error: /api/resize/
Traceback (most recent call last):
  File "/Users/key/PycharmProjects/python_dip_courseproject_django/venv/lib/python3.8/site-packages/django/core/handlers/exception.py", line 55, in inner
    response = get_response(request)
  File "/Users/key/PycharmProjects/python_dip_courseproject_django/venv/lib/python3.8/site-packages/django/core/handlers/base.py", line 197, in _get_response
    response = wrapped_callback(request, *callback_args, **callback_kwargs)
  File "/Users/key/PycharmProjects/python_dip_courseproject_django/venv/lib/python3.8/site-packages/django/views/decorators/csrf.py", line 54, in wrapped_view
    return view_func(*args, **kwargs)
  File "/Users/key/PycharmProjects/python_dip_courseproject_django/venv/lib/python3.8/site-packages/django/views/generic/base.py", line 84, in view
    return self.dispatch(request, *args, **kwargs)
  File "/Users/key/PycharmProjects/python_dip_courseproject_django/venv/lib/python3.8/site-packages/rest_framework/views.py", line 509, in dispatch
    response = self.handle_exception(exc)
  File "/Users/key/PycharmProjects/python_dip_courseproject_django/venv/lib/python3.8/site-packages/rest_framework/views.py", line 469, in handle_exception
    self.raise_uncaught_exception(exc)
  File "/Users/key/PycharmProjects/python_dip_courseproject_django/venv/lib/python3.8/site-packages/rest_framework/views.py", line 480, in raise_uncaught_exception
    raise exc
  File "/Users/key/PycharmProjects/python_dip_courseproject_django/venv/lib/python3.8/site-packages/rest_framework/views.py", line 506, in dispatch
    response = handler(request, *args, **kwargs)
  File "/Users/key/PycharmProjects/python_dip_courseproject_django/api/views.py", line 52, in post
    images = Image.objects.get(id=request.data.get('id'))
  File "/Users/key/PycharmProjects/python_dip_courseproject_django/venv/lib/python3.8/site-packages/django/db/models/manager.py", line 85, in manager_method
    return getattr(self.get_queryset(), name)(*args, **kwargs)
  File "/Users/key/PycharmProjects/python_dip_courseproject_django/venv/lib/python3.8/site-packages/django/db/models/query.py", line 496, in get
    raise self.model.DoesNotExist(
api.models.Image.DoesNotExist: Image matching query does not exist.
ERROR 2022-05-16 00:35:46,676 [Thread-7:6130003968] [django.request:241] [log:log_response] [ERROR]- Internal Server Error: /api/resize/
Traceback (most recent call last):
  File "/Users/key/PycharmProjects/python_dip_courseproject_django/venv/lib/python3.8/site-packages/django/core/handlers/exception.py", line 55, in inner
    response = get_response(request)
  File "/Users/key/PycharmProjects/python_dip_courseproject_django/venv/lib/python3.8/site-packages/django/core/handlers/base.py", line 197, in _get_response
    response = wrapped_callback(request, *callback_args, **callback_kwargs)
  File "/Users/key/PycharmProjects/python_dip_courseproject_django/venv/lib/python3.8/site-packages/django/views/decorators/csrf.py", line 54, in wrapped_view
    return view_func(*args, **kwargs)
  File "/Users/key/PycharmProjects/python_dip_courseproject_django/venv/lib/python3.8/site-packages/django/views/generic/base.py", line 84, in view
    return self.dispatch(request, *args, **kwargs)
  File "/Users/key/PycharmProjects/python_dip_courseproject_django/venv/lib/python3.8/site-packages/rest_framework/views.py", line 509, in dispatch
    response = self.handle_exception(exc)
  File "/Users/key/PycharmProjects/python_dip_courseproject_django/venv/lib/python3.8/site-packages/rest_framework/views.py", line 469, in handle_exception
    self.raise_uncaught_exception(exc)
  File "/Users/key/PycharmProjects/python_dip_courseproject_django/venv/lib/python3.8/site-packages/rest_framework/views.py", line 480, in raise_uncaught_exception
    raise exc
  File "/Users/key/PycharmProjects/python_dip_courseproject_django/venv/lib/python3.8/site-packages/rest_framework/views.py", line 506, in dispatch
    response = handler(request, *args, **kwargs)
  File "/Users/key/PycharmProjects/python_dip_courseproject_django/api/views.py", line 52, in post
    images = Image.objects.get(id=request.data.get('id'))
  File "/Users/key/PycharmProjects/python_dip_courseproject_django/venv/lib/python3.8/site-packages/django/db/models/manager.py", line 85, in manager_method
    return getattr(self.get_queryset(), name)(*args, **kwargs)
  File "/Users/key/PycharmProjects/python_dip_courseproject_django/venv/lib/python3.8/site-packages/django/db/models/query.py", line 496, in get
    raise self.model.DoesNotExist(
api.models.Image.DoesNotExist: Image matching query does not exist.
ERROR 2022-05-16 00:36:18,610 [Thread-7:6130003968] [django.request:241] [log:log_response] [ERROR]- Internal Server Error: /api/resize/
Traceback (most recent call last):
  File "/Users/key/PycharmProjects/python_dip_courseproject_django/venv/lib/python3.8/site-packages/django/core/handlers/exception.py", line 55, in inner
    response = get_response(request)
  File "/Users/key/PycharmProjects/python_dip_courseproject_django/venv/lib/python3.8/site-packages/django/core/handlers/base.py", line 197, in _get_response
    response = wrapped_callback(request, *callback_args, **callback_kwargs)
  File "/Users/key/PycharmProjects/python_dip_courseproject_django/venv/lib/python3.8/site-packages/django/views/decorators/csrf.py", line 54, in wrapped_view
    return view_func(*args, **kwargs)
  File "/Users/key/PycharmProjects/python_dip_courseproject_django/venv/lib/python3.8/site-packages/django/views/generic/base.py", line 84, in view
    return self.dispatch(request, *args, **kwargs)
  File "/Users/key/PycharmProjects/python_dip_courseproject_django/venv/lib/python3.8/site-packages/rest_framework/views.py", line 509, in dispatch
    response = self.handle_exception(exc)
  File "/Users/key/PycharmProjects/python_dip_courseproject_django/venv/lib/python3.8/site-packages/rest_framework/views.py", line 469, in handle_exception
    self.raise_uncaught_exception(exc)
  File "/Users/key/PycharmProjects/python_dip_courseproject_django/venv/lib/python3.8/site-packages/rest_framework/views.py", line 480, in raise_uncaught_exception
    raise exc
  File "/Users/key/PycharmProjects/python_dip_courseproject_django/venv/lib/python3.8/site-packages/rest_framework/views.py", line 506, in dispatch
    response = handler(request, *args, **kwargs)
  File "/Users/key/PycharmProjects/python_dip_courseproject_django/api/views.py", line 52, in post
    images = Image.objects.get(id=request.data.get('id'))
  File "/Users/key/PycharmProjects/python_dip_courseproject_django/venv/lib/python3.8/site-packages/django/db/models/manager.py", line 85, in manager_method
    return getattr(self.get_queryset(), name)(*args, **kwargs)
  File "/Users/key/PycharmProjects/python_dip_courseproject_django/venv/lib/python3.8/site-packages/django/db/models/query.py", line 496, in get
    raise self.model.DoesNotExist(
api.models.Image.DoesNotExist: Image matching query does not exist.
ERROR 2022-05-16 00:36:20,086 [Thread-7:6130003968] [django.request:241] [log:log_response] [ERROR]- Internal Server Error: /api/resize/
Traceback (most recent call last):
  File "/Users/key/PycharmProjects/python_dip_courseproject_django/venv/lib/python3.8/site-packages/django/core/handlers/exception.py", line 55, in inner
    response = get_response(request)
  File "/Users/key/PycharmProjects/python_dip_courseproject_django/venv/lib/python3.8/site-packages/django/core/handlers/base.py", line 197, in _get_response
    response = wrapped_callback(request, *callback_args, **callback_kwargs)
  File "/Users/key/PycharmProjects/python_dip_courseproject_django/venv/lib/python3.8/site-packages/django/views/decorators/csrf.py", line 54, in wrapped_view
    return view_func(*args, **kwargs)
  File "/Users/key/PycharmProjects/python_dip_courseproject_django/venv/lib/python3.8/site-packages/django/views/generic/base.py", line 84, in view
    return self.dispatch(request, *args, **kwargs)
  File "/Users/key/PycharmProjects/python_dip_courseproject_django/venv/lib/python3.8/site-packages/rest_framework/views.py", line 509, in dispatch
    response = self.handle_exception(exc)
  File "/Users/key/PycharmProjects/python_dip_courseproject_django/venv/lib/python3.8/site-packages/rest_framework/views.py", line 469, in handle_exception
    self.raise_uncaught_exception(exc)
  File "/Users/key/PycharmProjects/python_dip_courseproject_django/venv/lib/python3.8/site-packages/rest_framework/views.py", line 480, in raise_uncaught_exception
    raise exc
  File "/Users/key/PycharmProjects/python_dip_courseproject_django/venv/lib/python3.8/site-packages/rest_framework/views.py", line 506, in dispatch
    response = handler(request, *args, **kwargs)
  File "/Users/key/PycharmProjects/python_dip_courseproject_django/api/views.py", line 52, in post
    images = Image.objects.get(id=request.data.get('id'))
  File "/Users/key/PycharmProjects/python_dip_courseproject_django/venv/lib/python3.8/site-packages/django/db/models/manager.py", line 85, in manager_method
    return getattr(self.get_queryset(), name)(*args, **kwargs)
  File "/Users/key/PycharmProjects/python_dip_courseproject_django/venv/lib/python3.8/site-packages/django/db/models/query.py", line 496, in get
    raise self.model.DoesNotExist(
api.models.Image.DoesNotExist: Image matching query does not exist.
ERROR 2022-05-19 03:32:18,422 [Thread-5:6184611840] [django.request:241] [log:log_response] [ERROR]- Internal Server Error: /api/getHistArray/
Traceback (most recent call last):
  File "/Users/key/PycharmProjects/python_dip_courseproject_django/venv/lib/python3.8/site-packages/django/core/handlers/exception.py", line 55, in inner
    response = get_response(request)
  File "/Users/key/PycharmProjects/python_dip_courseproject_django/venv/lib/python3.8/site-packages/django/core/handlers/base.py", line 197, in _get_response
    response = wrapped_callback(request, *callback_args, **callback_kwargs)
  File "/Users/key/PycharmProjects/python_dip_courseproject_django/venv/lib/python3.8/site-packages/django/views/decorators/csrf.py", line 54, in wrapped_view
    return view_func(*args, **kwargs)
  File "/Users/key/PycharmProjects/python_dip_courseproject_django/venv/lib/python3.8/site-packages/django/views/generic/base.py", line 84, in view
    return self.dispatch(request, *args, **kwargs)
  File "/Users/key/PycharmProjects/python_dip_courseproject_django/venv/lib/python3.8/site-packages/rest_framework/views.py", line 509, in dispatch
    response = self.handle_exception(exc)
  File "/Users/key/PycharmProjects/python_dip_courseproject_django/venv/lib/python3.8/site-packages/rest_framework/views.py", line 469, in handle_exception
    self.raise_uncaught_exception(exc)
  File "/Users/key/PycharmProjects/python_dip_courseproject_django/venv/lib/python3.8/site-packages/rest_framework/views.py", line 480, in raise_uncaught_exception
    raise exc
  File "/Users/key/PycharmProjects/python_dip_courseproject_django/venv/lib/python3.8/site-packages/rest_framework/views.py", line 506, in dispatch
    response = handler(request, *args, **kwargs)
  File "/Users/key/PycharmProjects/python_dip_courseproject_django/api/views.py", line 70, in post
    histArray = get_hist_array(path)
  File "/Users/key/PycharmProjects/python_dip_courseproject_django/lib/manage/imageProcess.py", line 31, in get_hist_array
    if (img0 == img1 == img2).all():
ValueError: The truth value of an array with more than one element is ambiguous. Use a.any() or a.all()
ERROR 2022-05-19 03:33:09,462 [Thread-5:6325039104] [django.request:241] [log:log_response] [ERROR]- Internal Server Error: /api/getHistArray/
Traceback (most recent call last):
  File "/Users/key/PycharmProjects/python_dip_courseproject_django/venv/lib/python3.8/site-packages/django/core/handlers/exception.py", line 55, in inner
    response = get_response(request)
  File "/Users/key/PycharmProjects/python_dip_courseproject_django/venv/lib/python3.8/site-packages/django/core/handlers/base.py", line 197, in _get_response
    response = wrapped_callback(request, *callback_args, **callback_kwargs)
  File "/Users/key/PycharmProjects/python_dip_courseproject_django/venv/lib/python3.8/site-packages/django/views/decorators/csrf.py", line 54, in wrapped_view
    return view_func(*args, **kwargs)
  File "/Users/key/PycharmProjects/python_dip_courseproject_django/venv/lib/python3.8/site-packages/django/views/generic/base.py", line 84, in view
    return self.dispatch(request, *args, **kwargs)
  File "/Users/key/PycharmProjects/python_dip_courseproject_django/venv/lib/python3.8/site-packages/rest_framework/views.py", line 509, in dispatch
    response = self.handle_exception(exc)
  File "/Users/key/PycharmProjects/python_dip_courseproject_django/venv/lib/python3.8/site-packages/rest_framework/views.py", line 469, in handle_exception
    self.raise_uncaught_exception(exc)
  File "/Users/key/PycharmProjects/python_dip_courseproject_django/venv/lib/python3.8/site-packages/rest_framework/views.py", line 480, in raise_uncaught_exception
    raise exc
  File "/Users/key/PycharmProjects/python_dip_courseproject_django/venv/lib/python3.8/site-packages/rest_framework/views.py", line 506, in dispatch
    response = handler(request, *args, **kwargs)
  File "/Users/key/PycharmProjects/python_dip_courseproject_django/api/views.py", line 70, in post
    histArray = get_hist_array(path)
  File "/Users/key/PycharmProjects/python_dip_courseproject_django/lib/manage/imageProcess.py", line 31, in get_hist_array
    if (img0 == img1 == img2).all():
ValueError: The truth value of an array with more than one element is ambiguous. Use a.any() or a.all()
ERROR 2022-05-19 03:33:11,581 [Thread-5:6325039104] [django.request:241] [log:log_response] [ERROR]- Internal Server Error: /api/getHistArray/
Traceback (most recent call last):
  File "/Users/key/PycharmProjects/python_dip_courseproject_django/venv/lib/python3.8/site-packages/django/core/handlers/exception.py", line 55, in inner
    response = get_response(request)
  File "/Users/key/PycharmProjects/python_dip_courseproject_django/venv/lib/python3.8/site-packages/django/core/handlers/base.py", line 197, in _get_response
    response = wrapped_callback(request, *callback_args, **callback_kwargs)
  File "/Users/key/PycharmProjects/python_dip_courseproject_django/venv/lib/python3.8/site-packages/django/views/decorators/csrf.py", line 54, in wrapped_view
    return view_func(*args, **kwargs)
  File "/Users/key/PycharmProjects/python_dip_courseproject_django/venv/lib/python3.8/site-packages/django/views/generic/base.py", line 84, in view
    return self.dispatch(request, *args, **kwargs)
  File "/Users/key/PycharmProjects/python_dip_courseproject_django/venv/lib/python3.8/site-packages/rest_framework/views.py", line 509, in dispatch
    response = self.handle_exception(exc)
  File "/Users/key/PycharmProjects/python_dip_courseproject_django/venv/lib/python3.8/site-packages/rest_framework/views.py", line 469, in handle_exception
    self.raise_uncaught_exception(exc)
  File "/Users/key/PycharmProjects/python_dip_courseproject_django/venv/lib/python3.8/site-packages/rest_framework/views.py", line 480, in raise_uncaught_exception
    raise exc
  File "/Users/key/PycharmProjects/python_dip_courseproject_django/venv/lib/python3.8/site-packages/rest_framework/views.py", line 506, in dispatch
    response = handler(request, *args, **kwargs)
  File "/Users/key/PycharmProjects/python_dip_courseproject_django/api/views.py", line 70, in post
    histArray = get_hist_array(path)
  File "/Users/key/PycharmProjects/python_dip_courseproject_django/lib/manage/imageProcess.py", line 31, in get_hist_array
    if (img0 == img1 == img2).all():
ValueError: The truth value of an array with more than one element is ambiguous. Use a.any() or a.all()
ERROR 2022-05-28 15:35:28,840 [Thread-1:23216] [django.request:241] [log:log_response] [ERROR]- Internal Server Error: /api/resize/
Traceback (most recent call last):
  File "C:\Users\Zeho\Desktop\Code\django\venv\lib\site-packages\django\core\handlers\exception.py", line 55, in inner
    response = get_response(request)
  File "C:\Users\Zeho\Desktop\Code\django\venv\lib\site-packages\django\core\handlers\base.py", line 197, in _get_response
    response = wrapped_callback(request, *callback_args, **callback_kwargs)
  File "C:\Users\Zeho\Desktop\Code\django\venv\lib\site-packages\django\views\decorators\csrf.py", line 54, in wrapped_view
    return view_func(*args, **kwargs)
  File "C:\Users\Zeho\Desktop\Code\django\venv\lib\site-packages\django\views\generic\base.py", line 84, in view
    return self.dispatch(request, *args, **kwargs)
  File "C:\Users\Zeho\Desktop\Code\django\venv\lib\site-packages\rest_framework\views.py", line 509, in dispatch
    response = self.handle_exception(exc)
  File "C:\Users\Zeho\Desktop\Code\django\venv\lib\site-packages\rest_framework\views.py", line 469, in handle_exception
    self.raise_uncaught_exception(exc)
  File "C:\Users\Zeho\Desktop\Code\django\venv\lib\site-packages\rest_framework\views.py", line 480, in raise_uncaught_exception
    raise exc
  File "C:\Users\Zeho\Desktop\Code\django\venv\lib\site-packages\rest_framework\views.py", line 506, in dispatch
    response = handler(request, *args, **kwargs)
  File "C:\Users\Zeho\Documents\dmp_course-project\api\views.py", line 66, in post
    imageResize(zoomXValue, zoomYValue, path)
  File "C:\Users\Zeho\Documents\dmp_course-project\lib\manage\imageProcess.py", line 43, in imageResize
    x = float(x)
UnboundLocalError: local variable 'x' referenced before assignment
ERROR 2022-05-28 15:36:30,425 [Thread-1:23216] [django.request:241] [log:log_response] [ERROR]- Internal Server Error: /api/resize/
Traceback (most recent call last):
  File "C:\Users\Zeho\Desktop\Code\django\venv\lib\site-packages\django\core\handlers\exception.py", line 55, in inner
    response = get_response(request)
  File "C:\Users\Zeho\Desktop\Code\django\venv\lib\site-packages\django\core\handlers\base.py", line 197, in _get_response
    response = wrapped_callback(request, *callback_args, **callback_kwargs)
  File "C:\Users\Zeho\Desktop\Code\django\venv\lib\site-packages\django\views\decorators\csrf.py", line 54, in wrapped_view
    return view_func(*args, **kwargs)
  File "C:\Users\Zeho\Desktop\Code\django\venv\lib\site-packages\django\views\generic\base.py", line 84, in view
    return self.dispatch(request, *args, **kwargs)
  File "C:\Users\Zeho\Desktop\Code\django\venv\lib\site-packages\rest_framework\views.py", line 509, in dispatch
    response = self.handle_exception(exc)
  File "C:\Users\Zeho\Desktop\Code\django\venv\lib\site-packages\rest_framework\views.py", line 469, in handle_exception
    self.raise_uncaught_exception(exc)
  File "C:\Users\Zeho\Desktop\Code\django\venv\lib\site-packages\rest_framework\views.py", line 480, in raise_uncaught_exception
    raise exc
  File "C:\Users\Zeho\Desktop\Code\django\venv\lib\site-packages\rest_framework\views.py", line 506, in dispatch
    response = handler(request, *args, **kwargs)
  File "C:\Users\Zeho\Documents\dmp_course-project\api\views.py", line 66, in post
    imageResize(zoomXValue, zoomYValue, path)
  File "C:\Users\Zeho\Documents\dmp_course-project\lib\manage\imageProcess.py", line 43, in imageResize
    x = float(x)
UnboundLocalError: local variable 'x' referenced before assignment
ERROR 2022-05-28 15:38:08,626 [Thread-1:23216] [django.request:241] [log:log_response] [ERROR]- Internal Server Error: /api/resize/
Traceback (most recent call last):
  File "C:\Users\Zeho\Desktop\Code\django\venv\lib\site-packages\django\core\handlers\exception.py", line 55, in inner
    response = get_response(request)
  File "C:\Users\Zeho\Desktop\Code\django\venv\lib\site-packages\django\core\handlers\base.py", line 197, in _get_response
    response = wrapped_callback(request, *callback_args, **callback_kwargs)
  File "C:\Users\Zeho\Desktop\Code\django\venv\lib\site-packages\django\views\decorators\csrf.py", line 54, in wrapped_view
    return view_func(*args, **kwargs)
  File "C:\Users\Zeho\Desktop\Code\django\venv\lib\site-packages\django\views\generic\base.py", line 84, in view
    return self.dispatch(request, *args, **kwargs)
  File "C:\Users\Zeho\Desktop\Code\django\venv\lib\site-packages\rest_framework\views.py", line 509, in dispatch
    response = self.handle_exception(exc)
  File "C:\Users\Zeho\Desktop\Code\django\venv\lib\site-packages\rest_framework\views.py", line 469, in handle_exception
    self.raise_uncaught_exception(exc)
  File "C:\Users\Zeho\Desktop\Code\django\venv\lib\site-packages\rest_framework\views.py", line 480, in raise_uncaught_exception
    raise exc
  File "C:\Users\Zeho\Desktop\Code\django\venv\lib\site-packages\rest_framework\views.py", line 506, in dispatch
    response = handler(request, *args, **kwargs)
  File "C:\Users\Zeho\Documents\dmp_course-project\api\views.py", line 66, in post
    imageResize(zoomXValue, zoomYValue, path)
  File "C:\Users\Zeho\Documents\dmp_course-project\lib\manage\imageProcess.py", line 43, in imageResize
    x = float(x)
UnboundLocalError: local variable 'x' referenced before assignment
WARNING 2022-05-28 15:38:48,728 [Thread-12:3576] [django.request:241] [log:log_response] [WARNING]- Method Not Allowed: /api/resize/
WARNING 2022-05-28 15:38:49,612 [Thread-13:9928] [django.request:241] [log:log_response] [WARNING]- Not Found: /favicon.ico
WARNING 2022-05-28 15:43:10,724 [Thread-1:21084] [django.request:241] [log:log_response] [WARNING]- Not Found: /
